Workbook

Sheet 01 Cover & Control
B4: Commercial Brokerage Revenue Forecasting & Pricing Model
B5: Driver-Based Operating Model — Commercial Real Estate Advisory Firm
B8: MODEL METADATA
B9: Company Name | C9: Apex CRE Advisors
B10: Model Version | C10: V1.0
B11: Prepared By | C11: Muhammed Sheikh
B12: Date | C12: 46196
B13: Status | C13: Completed
B14: Forecast Base Date | C14: Q1 2026
B15: Historical Period | C15: 2023A – 2025A
B16: Forecast Period | C16: 2026E – 2030E
B18: SCENARIO CONTROL
B19: Active Scenario | C19: Base | D19: <-- This cell drives all scenario-sensitive assumptions in Tabs 02 & 03
B20: Scenario Status | C20: =IF($C$19="Base","BASE CASE ACTIVE",IF($C$19="Upside","UPSIDE CASE ACTIVE",IF($C$19="Downside","DOWNSIDE CASE ACTIVE","— SELECT SCENARIO —"))) -> BASE CASE ACTIVE
B22: MODEL INTEGRITY STATUS
B23: Check Status | C23: =IF('11 Checks'!$F$9>0,"FAIL",IF('11 Checks'!$H$9>0,"PASS WITH WARNINGS","PASS")) -> PASS WITH WARNINGS
C24: Live status reflects critical failures and advisory warnings from Tab 11. See Tab 11 for detailed audit results.
B26: TOP-LINE SUMMARY MIRROR [ Linked to Tab 08 P&L Annual Summary ]
B27: Metric | C27: Units | D27: 2023A | E27: 2024A | F27: 2025A | G27: 2026E | H27: 2027E | I27: 2028E | J27: 2029E | K27: 2030E
B28: Total GCI | C28: $K | D28: ='08 P&L'!I97 -> 167707.94 | E28: ='08 P&L'!N97 -> 200982.97 | F28: ='08 P&L'!S97 -> 233698.5 | G28: ='08 P&L'!X97 -> 262289.94 | H28: ='08 P&L'!AC97 -> 290016.09 | I28: ='08 P&L'!AH97 -> 313002.15 | J28: ='08 P&L'!AM97 -> 334879.56 | K28: ='08 P&L'!AR97 -> 357566.72
B29: Leasing GCI | C29: $K | D29: ='08 P&L'!I93 -> 66192.187 | E29: ='08 P&L'!N93 -> 83285.798 | F29: ='08 P&L'!S93 -> 98924.839 | G29: ='08 P&L'!X93 -> 113320.1 | H29: ='08 P&L'!AC93 -> 126650.33 | I29: ='08 P&L'!AH93 -> 139067.1 | J29: ='08 P&L'!AM93 -> 150698.85 | K29: ='08 P&L'!AR93 -> 161654.55
B30: Investment Sales GCI | C30: $K | D30: ='08 P&L'!I94 -> 57764.133 | E30: ='08 P&L'!N94 -> 69176.662 | F30: ='08 P&L'!S94 -> 81068.929 | G30: ='08 P&L'!X94 -> 90124.081 | H30: ='08 P&L'!AC94 -> 100119.28 | I30: ='08 P&L'!AH94 -> 107396.6 | J30: ='08 P&L'!AM94 -> 114183.83 | K30: ='08 P&L'!AR94 -> 122278.85
B31: D&E Placement GCI | C31: $K | D31: ='08 P&L'!I95 -> 35579.694 | E31: ='08 P&L'!N95 -> 39222.139 | F31: ='08 P&L'!S95 -> 43427.593 | G31: ='08 P&L'!X95 -> 47713.929 | H31: ='08 P&L'!AC95 -> 51364.625 | I31: ='08 P&L'!AH95 -> 53995.283 | J31: ='08 P&L'!AM95 -> 56867.844 | K31: ='08 P&L'!AR95 -> 59982.955
B32: Advisory Revenue | C32: $K | D32: ='08 P&L'!I96 -> 8171.9308 | E32: ='08 P&L'!N96 -> 9298.372 | F32: ='08 P&L'!S96 -> 10277.143 | G32: ='08 P&L'!X96 -> 11131.838 | H32: ='08 P&L'!AC96 -> 11881.853 | I32: ='08 P&L'!AH96 -> 12543.179 | J32: ='08 P&L'!AM96 -> 13129.029 | K32: ='08 P&L'!AR96 -> 13650.359
B33: Producer Payouts | C33: $K | D33: ='08 P&L'!I99 -> 119159.3 | E33: ='08 P&L'!N99 -> 143107.12 | F33: ='08 P&L'!S99 -> 166770.52 | G33: ='08 P&L'!X99 -> 187460.1 | H33: ='08 P&L'!AC99 -> 207592.42 | I33: ='08 P&L'!AH99 -> 224280.64 | J33: ='08 P&L'!AM99 -> 240183.28 | K33: ='08 P&L'!AR99 -> 256769.99
B34: Company Dollar | C34: $K | D34: ='08 P&L'!I100 -> 48548.64 | E34: ='08 P&L'!N100 -> 57875.854 | F34: ='08 P&L'!S100 -> 66927.982 | G34: ='08 P&L'!X100 -> 74829.84 | H34: ='08 P&L'!AC100 -> 82423.67 | I34: ='08 P&L'!AH100 -> 88721.511 | J34: ='08 P&L'!AM100 -> 94696.284 | K34: ='08 P&L'!AR100 -> 100796.72
B35: Company Dollar Margin % | C35: % | D35: ='08 P&L'!I101 -> 0.28948325 | E35: ='08 P&L'!N101 -> 0.28796397 | F35: ='08 P&L'!S101 -> 0.28638601 | G35: ='08 P&L'!X101 -> 0.28529435 | H35: ='08 P&L'!AC101 -> 0.28420378 | I35: ='08 P&L'!AH101 -> 0.28345336 | J35: ='08 P&L'!AM101 -> 0.28277714 | K35: ='08 P&L'!AR101 -> 0.28189627
B36: Total Operating Expenses | C36: $K | D36: ='08 P&L'!I103 -> 34503.263 | E36: ='08 P&L'!N103 -> 38321.534 | F36: ='08 P&L'!S103 -> 41843.558 | G36: ='08 P&L'!X103 -> 37019.454 | H36: ='08 P&L'!AC103 -> 38999.546 | I36: ='08 P&L'!AH103 -> 40670.438 | J36: ='08 P&L'!AM103 -> 42182.537 | K36: ='08 P&L'!AR103 -> 43616.874
B37: EBITDA | C37: $K | D37: ='08 P&L'!I104 -> 14045.378 | E37: ='08 P&L'!N104 -> 19554.32 | F37: ='08 P&L'!S104 -> 25084.424 | G37: ='08 P&L'!X104 -> 37810.386 | H37: ='08 P&L'!AC104 -> 43424.124 | I37: ='08 P&L'!AH104 -> 48051.073 | J37: ='08 P&L'!AM104 -> 52513.747 | K37: ='08 P&L'!AR104 -> 57179.849
B38: EBITDA Margin on GCI % | C38: % | D38: ='08 P&L'!I105 -> 0.083749029 | E38: ='08 P&L'!N105 -> 0.097293417 | F38: ='08 P&L'!S105 -> 0.10733669 | G38: ='08 P&L'!X105 -> 0.14415492 | H38: ='08 P&L'!AC105 -> 0.14973005 | I38: ='08 P&L'!AH105 -> 0.15351675 | J38: ='08 P&L'!AM105 -> 0.15681383 | K38: ='08 P&L'!AR105 -> 0.15991379
B39: Total EPEs (Firm) | C39: # | D39: ='04 Producer Engine'!I213 -> 107.70544 | E39: ='04 Producer Engine'!N213 -> 131.44912 | F39: ='04 Producer Engine'!S213 -> 151.18987 | G39: ='04 Producer Engine'!X213 -> 167.6685 | H39: ='04 Producer Engine'!AC213 -> 181.48096 | I39: ='04 Producer Engine'!AH213 -> 193.10761 | J39: ='04 Producer Engine'!AM213 -> 202.93647 | K39: ='04 Producer Engine'!AR213 -> 211.28174
B40: Effective Payout Ratio | C40: % | D40: ='08 P&L'!I30 -> 0.71051675 | E40: ='08 P&L'!N30 -> 0.71203603 | F40: ='08 P&L'!S30 -> 0.71361399 | G40: ='08 P&L'!X30 -> 0.71470565 | H40: ='08 P&L'!AC30 -> 0.71579622 | I40: ='08 P&L'!AH30 -> 0.71654664 | J40: ='08 P&L'!AM30 -> 0.71722286 | K40: ='08 P&L'!AR30 -> 0.71810373
B41: Note: Forecast assumes no financing structure and applies a 26.0% illustrative effective tax rate to pre-tax operating income. After-Tax Operating Income (Unlevered) is shown before any interest, financing, or capital-structure effects.
B42: TAB DIRECTORY
B43: Tab # | C43: Tab Name | E43: Type | F43: Purpose (one line)
B44: 01 | C44: Cover & Control | E44: Input / Nav | F44: Model identity, scenario selector, summary mirror, tab directory, color legend.
B45: 02 | C45: Market Assumptions | E45: Input | F45: Exogenous market drivers: IS volume, leasing volume, originations, fee rates, macro context.
B46: 03 | C46: Operational Assumptions | E46: Input | F46: Firm-controlled drivers: headcount plan, productivity, comp structure, opex drivers.
B47: 04 | C47: Producer Engine | E47: Engine | F47: Headcount roll-forward → ramp-adjusted EPEs → book loss GCI drag by line and tier.
B48: 05 | C48: Revenue Engine | E48: Engine | F48: GCI build for Leasing, IS, D&E, and Advisory; revenue bridge; market-share diagnostic.
...

Sheet 02 Market Assumptions
A1: 02 | MARKET ASSUMPTIONS — EXOGENOUS DRIVERS
A2: Scenario-sensitive rows use Base / Upside / Downside / Active pattern. Active rows link to Tab 01 C19. | E2: ='01 Cover & Control'!C19 -> Base
B3: Assumption / Row | C3: Units | D3: Source / Notes | E3: 2023A Q1 | F3: 2023A Q2 | G3: 2023A Q3 | H3: 2023A Q4 | I3: 2023A Annual | J3: 2024A Q1 | K3: 2024A Q2 | L3: 2024A Q3 | M3: 2024A Q4 | N3: 2024A Annual | O3: 2025A Q1 | P3: 2025A Q2 | Q3: 2025A Q3 | R3: 2025A Q4 | S3: 2025A Annual | T3: 2026E Q1 | U3: 2026E Q2 | V3: 2026E Q3 | W3: 2026E Q4 | X3: 2026E Annual | Y3: 2027E Q1 | Z3: 2027E Q2 | AA3: 2027E Q3 | AB3: 2027E Q4 | AC3: 2027E Annual | AD3: 2028E Q1 | AE3: 2028E Q2 | AF3: 2028E Q3 | AG3: 2028E Q4 | AH3: 2028E Annual | AI3: 2029E Q1 | AJ3: 2029E Q2 | AK3: 2029E Q3 | AL3: 2029E Q4 | AM3: 2029E Annual | AN3: 2030E Q1 | AO3: 2030E Q2 | AP3: 2030E Q3 | AQ3: 2030E Q4 | AR3: 2030E Annual
A5: SECTION A — MACRO CONTEXT
B7: Real GDP Growth (YoY) — Base | C7: % / yr | D7: BEA GDP Release; Bloomberg consensus forecast | E7: 1.8 | F7: 1.8 | G7: 1.8 | H7: 1.8 | I7: =SUM(E7:H7) -> 7.2 | J7: 2.1 | K7: 2.1 | L7: 2.1 | M7: 2.1 | N7: =SUM(J7:M7) -> 8.4 | O7: 2.4 | P7: 2.4 | Q7: 2.4 | R7: 2.4 | S7: =SUM(O7:R7) -> 9.6 | T7: 2.2 | U7: 2.2 | V7: 2.2 | W7: 2.2 | X7: =SUM(T7:W7) -> 8.8 | Y7: 2 | Z7: 2 | AA7: 2 | AB7: 2 | AC7: =SUM(Y7:AB7) -> 8 | AD7: 2 | AE7: 2 | AF7: 2 | AG7: 2 | AH7: =SUM(AD7:AG7) -> 8 | AI7: 2 | AJ7: 2 | AK7: 2 | AL7: 2 | AM7: =SUM(AI7:AL7) -> 8 | AN7: 2 | AO7: 2 | AP7: 2 | AQ7: 2 | AR7: =SUM(AN7:AQ7) -> 8
B8: Real GDP Growth (YoY) — Upside | E8: 1.8 | F8: 1.8 | G8: 1.8 | H8: 1.8 | I8: =SUM(E8:H8) -> 7.2 | J8: 2.1 | K8: 2.1 | L8: 2.1 | M8: 2.1 | N8: =SUM(J8:M8) -> 8.4 | O8: 2.6 | P8: 2.6 | Q8: 2.6 | R8: 2.6 | S8: =SUM(O8:R8) -> 10.4 | T8: 2.8 | U8: 2.8 | V8: 2.8 | W8: 2.8 | X8: =SUM(T8:W8) -> 11.2 | Y8: 2.7 | Z8: 2.7 | AA8: 2.7 | AB8: 2.7 | AC8: =SUM(Y8:AB8) -> 10.8 | AD8: 2.6 | AE8: 2.6 | AF8: 2.6 | AG8: 2.6 | AH8: =SUM(AD8:AG8) -> 10.4 | AI8: 2.5 | AJ8: 2.5 | AK8: 2.5 | AL8: 2.5 | AM8: =SUM(AI8:AL8) -> 10 | AN8: 2.5 | AO8: 2.5 | AP8: 2.5 | AQ8: 2.5 | AR8: =SUM(AN8:AQ8) -> 10
B9: Real GDP Growth (YoY) — Downside | E9: 1.8 | F9: 1.8 | G9: 1.8 | H9: 1.8 | I9: =SUM(E9:H9) -> 7.2 | J9: 2.1 | K9: 2.1 | L9: 2.1 | M9: 2.1 | N9: =SUM(J9:M9) -> 8.4 | O9: 1.2 | P9: 1.2 | Q9: 1.2 | R9: 1.2 | S9: =SUM(O9:R9) -> 4.8 | T9: 0.4 | U9: 0.4 | V9: 0.4 | W9: 0.4 | X9: =SUM(T9:W9) -> 1.6 | Y9: 0.8 | Z9: 0.8 | AA9: 0.8 | AB9: 0.8 | AC9: =SUM(Y9:AB9) -> 3.2 | AD9: 1.2 | AE9: 1.2 | AF9: 1.2 | AG9: 1.2 | AH9: =SUM(AD9:AG9) -> 4.8 | AI9: 1.5 | AJ9: 1.5 | AK9: 1.5 | AL9: 1.5 | AM9: =SUM(AI9:AL9) -> 6 | AN9: 1.6 | AO9: 1.6 | AP9: 1.6 | AQ9: 1.6 | AR9: =SUM(AN9:AQ9) -> 6.4
B10: Real GDP Growth (YoY) — ★ ACTIVE | E10: =IF('01 Cover & Control'!$C$19="Base",E7,IF('01 Cover & Control'!$C$19="Upside",E8,E9)) -> 1.8 | F10: =IF('01 Cover & Control'!$C$19="Base",F7,IF('01 Cover & Control'!$C$19="Upside",F8,F9)) -> 1.8 | G10: =IF('01 Cover & Control'!$C$19="Base",G7,IF('01 Cover & Control'!$C$19="Upside",G8,G9)) -> 1.8 | H10: =IF('01 Cover & Control'!$C$19="Base",H7,IF('01 Cover & Control'!$C$19="Upside",H8,H9)) -> 1.8 | I10: =SUM(E10:H10) -> 7.2 | J10: =IF('01 Cover & Control'!$C$19="Base",J7,IF('01 Cover & Control'!$C$19="Upside",J8,J9)) -> 2.1 | K10: =IF('01 Cover & Control'!$C$19="Base",K7,IF('01 Cover & Control'!$C$19="Upside",K8,K9)) -> 2.1 | L10: =IF('01 Cover & Control'!$C$19="Base",L7,IF('01 Cover & Control'!$C$19="Upside",L8,L9)) -> 2.1 | M10: =IF('01 Cover & Control'!$C$19="Base",M7,IF('01 Cover & Control'!$C$19="Upside",M8,M9)) -> 2.1 | N10: =SUM(J10:M10) -> 8.4 | O10: =IF('01 Cover & Control'!$C$19="Base",O7,IF('01 Cover & Control'!$C$19="Upside",O8,O9)) -> 2.4 | P10: =IF('01 Cover & Control'!$C$19="Base",P7,IF('01 Cover & Control'!$C$19="Upside",P8,P9)) -> 2.4 | Q10: =IF('01 Cover & Control'!$C$19="Base",Q7,IF('01 Cover & Control'!$C$19="Upside",Q8,Q9)) -> 2.4 | R10: =IF('01 Cover & Control'!$C$19="Base",R7,IF('01 Cover & Control'!$C$19="Upside",R8,R9)) -> 2.4 | S10: =SUM(O10:R10) -> 9.6 | T10: =IF('01 Cover & Control'!$C$19="Base",T7,IF('01 Cover & Control'!$C$19="Upside",T8,T9)) -> 2.2 | U10: =IF('01 Cover & Control'!$C$19="Base",U7,IF('01 Cover & Control'!$C$19="Upside",U8,U9)) -> 2.2 | V10: =IF('01 Cover & Control'!$C$19="Base",V7,IF('01 Cover & Control'!$C$19="Upside",V8,V9)) -> 2.2 | W10: =IF('01 Cover & Control'!$C$19="Base",W7,IF('01 Cover & Control'!$C$19="Upside",W8,W9)) -> 2.2 | X10: =SUM(T10:W10) -> 8.8 | Y10: =IF('01 Cover & Control'!$C$19="Base",Y7,IF('01 Cover & Control'!$C$19="Upside",Y8,Y9)) -> 2 | Z10: =IF('01 Cover & Control'!$C$19="Base",Z7,IF('01 Cover & Control'!$C$19="Upside",Z8,Z9)) -> 2 | AA10: =IF('01 Cover & Control'!$C$19="Base",AA7,IF('01 Cover & Control'!$C$19="Upside",AA8,AA9)) -> 2 | AB10: =IF('01 Cover & Control'!$C$19="Base",AB7,IF('01 Cover & Control'!$C$19="Upside",AB8,AB9)) -> 2 | AC10: =SUM(Y10:AB10) -> 8 | AD10: =IF('01 Cover & Control'!$C$19="Base",AD7,IF('01 Cover & Control'!$C$19="Upside",AD8,AD9)) -> 2 | AE10: =IF('01 Cover & Control'!$C$19="Base",AE7,IF('01 Cover & Control'!$C$19="Upside",AE8,AE9)) -> 2 | AF10: =IF('01 Cover & Control'!$C$19="Base",AF7,IF('01 Cover & Control'!$C$19="Upside",AF8,AF9)) -> 2 | AG10: =IF('01 Cover & Control'!$C$19="Base",AG7,IF('01 Cover & Control'!$C$19="Upside",AG8,AG9)) -> 2 | AH10: =SUM(AD10:AG10) -> 8 | AI10: =IF('01 Cover & Control'!$C$19="Base",AI7,IF('01 Cover & Control'!$C$19="Upside",AI8,AI9)) -> 2 | AJ10: =IF('01 Cover & Control'!$C$19="Base",AJ7,IF('01 Cover & Control'!$C$19="Upside",AJ8,AJ9)) -> 2 | AK10: =IF('01 Cover & Control'!$C$19="Base",AK7,IF('01 Cover & Control'!$C$19="Upside",AK8,AK9)) -> 2 | AL10: =IF('01 Cover & Control'!$C$19="Base",AL7,IF('01 Cover & Control'!$C$19="Upside",AL8,AL9)) -> 2 | AM10: =SUM(AI10:AL10) -> 8 | AN10: =IF('01 Cover & Control'!$C$19="Base",AN7,IF('01 Cover & Control'!$C$19="Upside",AN8,AN9)) -> 2 | AO10: =IF('01 Cover & Control'!$C$19="Base",AO7,IF('01 Cover & Control'!$C$19="Upside",AO8,AO9)) -> 2 | AP10: =IF('01 Cover & Control'!$C$19="Base",AP7,IF('01 Cover & Control'!$C$19="Upside",AP8,AP9)) -> 2 | AQ10: =IF('01 Cover & Control'!$C$19="Base",AQ7,IF('01 Cover & Control'!$C$19="Upside",AQ8,AQ9)) -> 2 | AR10: =SUM(AN10:AQ10) -> 8
B12: 10-Year Treasury Yield — Base | C12: % | D12: Federal Reserve H.15; Bloomberg | E12: 3.9 | F12: 3.9 | G12: 3.9 | H12: 3.9 | I12: =SUM(E12:H12) -> 15.6 | J12: 4.2 | K12: 4.2 | L12: 4.2 | M12: 4.2 | N12: =SUM(J12:M12) -> 16.8 | O12: 4.3 | P12: 4.3 | Q12: 4.3 | R12: 4.3 | S12: =SUM(O12:R12) -> 17.2 | T12: 4 | U12: 4 | V12: 4 | W12: 4 | X12: =SUM(T12:W12) -> 16 | Y12: 3.8 | Z12: 3.8 | AA12: 3.8 | AB12: 3.8 | AC12: =SUM(Y12:AB12) -> 15.2 | AD12: 3.7 | AE12: 3.7 | AF12: 3.7 | AG12: 3.7 | AH12: =SUM(AD12:AG12) -> 14.8 | AI12: 3.7 | AJ12: 3.7 | AK12: 3.7 | AL12: 3.7 | AM12: =SUM(AI12:AL12) -> 14.8 | AN12: 3.7 | AO12: 3.7 | AP12: 3.7 | AQ12: 3.7 | AR12: =SUM(AN12:AQ12) -> 14.8
B13: 10-Year Treasury Yield — Upside | E13: 3.9 | F13: 3.9 | G13: 3.9 | H13: 3.9 | I13: =SUM(E13:H13) -> 15.6 | J13: 4.2 | K13: 4.2 | L13: 4.2 | M13: 4.2 | N13: =SUM(J13:M13) -> 16.8 | O13: 4 | P13: 4 | Q13: 4 | R13: 4 | S13: =SUM(O13:R13) -> 16 | T13: 3.5 | U13: 3.5 | V13: 3.5 | W13: 3.5 | X13: =SUM(T13:W13) -> 14 | Y13: 3.3 | Z13: 3.3 | AA13: 3.3 | AB13: 3.3 | AC13: =SUM(Y13:AB13) -> 13.2 | AD13: 3.2 | AE13: 3.2 | AF13: 3.2 | AG13: 3.2 | AH13: =SUM(AD13:AG13) -> 12.8 | AI13: 3.2 | AJ13: 3.2 | AK13: 3.2 | AL13: 3.2 | AM13: =SUM(AI13:AL13) -> 12.8 | AN13: 3.2 | AO13: 3.2 | AP13: 3.2 | AQ13: 3.2 | AR13: =SUM(AN13:AQ13) -> 12.8
B14: 10-Year Treasury Yield — Downside | E14: 3.9 | F14: 3.9 | G14: 3.9 | H14: 3.9 | I14: =SUM(E14:H14) -> 15.6 | J14: 4.2 | K14: 4.2 | L14: 4.2 | M14: 4.2 | N14: =SUM(J14:M14) -> 16.8 | O14: 4.8 | P14: 4.8 | Q14: 4.8 | R14: 4.8 | S14: =SUM(O14:R14) -> 19.2 | T14: 5 | U14: 5 | V14: 5 | W14: 5 | X14: =SUM(T14:W14) -> 20 | Y14: 4.8 | Z14: 4.8 | AA14: 4.8 | AB14: 4.8 | AC14: =SUM(Y14:AB14) -> 19.2 | AD14: 4.6 | AE14: 4.6 | AF14: 4.6 | AG14: 4.6 | AH14: =SUM(AD14:AG14) -> 18.4 | AI14: 4.5 | AJ14: 4.5 | AK14: 4.5 | AL14: 4.5 | AM14: =SUM(AI14:AL14) -> 18 | AN14: 4.4 | AO14: 4.4 | AP14: 4.4 | AQ14: 4.4 | AR14: =SUM(AN14:AQ14) -> 17.6
B15: 10-Year Treasury Yield — ★ ACTIVE | E15: =IF('01 Cover & Control'!$C$19="Base",E12,IF('01 Cover & Control'!$C$19="Upside",E13,E14)) -> 3.9 | F15: =IF('01 Cover & Control'!$C$19="Base",F12,IF('01 Cover & Control'!$C$19="Upside",F13,F14)) -> 3.9 | G15: =IF('01 Cover & Control'!$C$19="Base",G12,IF('01 Cover & Control'!$C$19="Upside",G13,G14)) -> 3.9 | H15: =IF('01 Cover & Control'!$C$19="Base",H12,IF('01 Cover & Control'!$C$19="Upside",H13,H14)) -> 3.9 | I15: =SUM(E15:H15) -> 15.6 | J15: =IF('01 Cover & Control'!$C$19="Base",J12,IF('01 Cover & Control'!$C$19="Upside",J13,J14)) -> 4.2 | K15: =IF('01 Cover & Control'!$C$19="Base",K12,IF('01 Cover & Control'!$C$19="Upside",K13,K14)) -> 4.2 | L15: =IF('01 Cover & Control'!$C$19="Base",L12,IF('01 Cover & Control'!$C$19="Upside",L13,L14)) -> 4.2 | M15: =IF('01 Cover & Control'!$C$19="Base",M12,IF('01 Cover & Control'!$C$19="Upside",M13,M14)) -> 4.2 | N15: =SUM(J15:M15) -> 16.8 | O15: =IF('01 Cover & Control'!$C$19="Base",O12,IF('01 Cover & Control'!$C$19="Upside",O13,O14)) -> 4.3 | P15: =IF('01 Cover & Control'!$C$19="Base",P12,IF('01 Cover & Control'!$C$19="Upside",P13,P14)) -> 4.3 | Q15: =IF('01 Cover & Control'!$C$19="Base",Q12,IF('01 Cover & Control'!$C$19="Upside",Q13,Q14)) -> 4.3 | R15: =IF('01 Cover & Control'!$C$19="Base",R12,IF('01 Cover & Control'!$C$19="Upside",R13,R14)) -> 4.3 | S15: =SUM(O15:R15) -> 17.2 | T15: =IF('01 Cover & Control'!$C$19="Base",T12,IF('01 Cover & Control'!$C$19="Upside",T13,T14)) -> 4 | U15: =IF('01 Cover & Control'!$C$19="Base",U12,IF('01 Cover & Control'!$C$19="Upside",U13,U14)) -> 4 | V15: =IF('01 Cover & Control'!$C$19="Base",V12,IF('01 Cover & Control'!$C$19="Upside",V13,V14)) -> 4 | W15: =IF('01 Cover & Control'!$C$19="Base",W12,IF('01 Cover & Control'!$C$19="Upside",W13,W14)) -> 4 | X15: =SUM(T15:W15) -> 16 | Y15: =IF('01 Cover & Control'!$C$19="Base",Y12,IF('01 Cover & Control'!$C$19="Upside",Y13,Y14)) -> 3.8 | Z15: =IF('01 Cover & Control'!$C$19="Base",Z12,IF('01 Cover & Control'!$C$19="Upside",Z13,Z14)) -> 3.8 | AA15: =IF('01 Cover & Control'!$C$19="Base",AA12,IF('01 Cover & Control'!$C$19="Upside",AA13,AA14)) -> 3.8 | AB15: =IF('01 Cover & Control'!$C$19="Base",AB12,IF('01 Cover & Control'!$C$19="Upside",AB13,AB14)) -> 3.8 | AC15: =SUM(Y15:AB15) -> 15.2 | AD15: =IF('01 Cover & Control'!$C$19="Base",AD12,IF('01 Cover & Control'!$C$19="Upside",AD13,AD14)) -> 3.7 | AE15: =IF('01 Cover & Control'!$C$19="Base",AE12,IF('01 Cover & Control'!$C$19="Upside",AE13,AE14)) -> 3.7 | AF15: =IF('01 Cover & Control'!$C$19="Base",AF12,IF('01 Cover & Control'!$C$19="Upside",AF13,AF14)) -> 3.7 | AG15: =IF('01 Cover & Control'!$C$19="Base",AG12,IF('01 Cover & Control'!$C$19="Upside",AG13,AG14)) -> 3.7 | AH15: =SUM(AD15:AG15) -> 14.8 | AI15: =IF('01 Cover & Control'!$C$19="Base",AI12,IF('01 Cover & Control'!$C$19="Upside",AI13,AI14)) -> 3.7 | AJ15: =IF('01 Cover & Control'!$C$19="Base",AJ12,IF('01 Cover & Control'!$C$19="Upside",AJ13,AJ14)) -> 3.7 | AK15: =IF('01 Cover & Control'!$C$19="Base",AK12,IF('01 Cover & Control'!$C$19="Upside",AK13,AK14)) -> 3.7 | AL15: =IF('01 Cover & Control'!$C$19="Base",AL12,IF('01 Cover & Control'!$C$19="Upside",AL13,AL14)) -> 3.7 | AM15: =SUM(AI15:AL15) -> 14.8 | AN15: =IF('01 Cover & Control'!$C$19="Base",AN12,IF('01 Cover & Control'!$C$19="Upside",AN13,AN14)) -> 3.7 | AO15: =IF('01 Cover & Control'!$C$19="Base",AO12,IF('01 Cover & Control'!$C$19="Upside",AO13,AO14)) -> 3.7 | AP15: =IF('01 Cover & Control'!$C$19="Base",AP12,IF('01 Cover & Control'!$C$19="Upside",AP13,AP14)) -> 3.7 | AQ15: =IF('01 Cover & Control'!$C$19="Base",AQ12,IF('01 Cover & Control'!$C$19="Upside",AQ13,AQ14)) -> 3.7 | AR15: =SUM(AN15:AQ15) -> 14.8
B17: Note: Lending Availability coded as 1=Tight, 2=Normal, 3=Loose. Used as qualitative context to calibrate Tab 03 deal count and pull-through assumptions.
B18: CRE Lending Availability Index — Base | C18: 1/2/3 | D18: CBRE Senior Loan Officer Survey; Fed Survey of Credit Conditions | E18: 1.5 | F18: 1.5 | G18: 1.5 | H18: 1.5 | I18: =SUM(E18:H18) -> 6 | J18: 1.6 | K18: 1.6 | L18: 1.6 | M18: 1.6 | N18: =SUM(J18:M18) -> 6.4 | O18: 1.8 | P18: 1.8 | Q18: 1.8 | R18: 1.8 | S18: =SUM(O18:R18) -> 7.2 | T18: 2 | U18: 2 | V18: 2 | W18: 2 | X18: =SUM(T18:W18) -> 8 | Y18: 2.1 | Z18: 2.1 | AA18: 2.1 | AB18: 2.1 | AC18: =SUM(Y18:AB18) -> 8.4 | AD18: 2.2 | AE18: 2.2 | AF18: 2.2 | AG18: 2.2 | AH18: =SUM(AD18:AG18) -> 8.8 | AI18: 2.2 | AJ18: 2.2 | AK18: 2.2 | AL18: 2.2 | AM18: =SUM(AI18:AL18) -> 8.8 | AN18: 2.2 | AO18: 2.2 | AP18: 2.2 | AQ18: 2.2 | AR18: =SUM(AN18:AQ18) -> 8.8
B19: CRE Lending Availability Index — Upside | E19: 1.5 | F19: 1.5 | G19: 1.5 | H19: 1.5 | I19: =SUM(E19:H19) -> 6 | J19: 1.6 | K19: 1.6 | L19: 1.6 | M19: 1.6 | N19: =SUM(J19:M19) -> 6.4 | O19: 2 | P19: 2 | Q19: 2 | R19: 2 | S19: =SUM(O19:R19) -> 8 | T19: 2.3 | U19: 2.3 | V19: 2.3 | W19: 2.3 | X19: =SUM(T19:W19) -> 9.2 | Y19: 2.5 | Z19: 2.5 | AA19: 2.5 | AB19: 2.5 | AC19: =SUM(Y19:AB19) -> 10 | AD19: 2.6 | AE19: 2.6 | AF19: 2.6 | AG19: 2.6 | AH19: =SUM(AD19:AG19) -> 10.4 | AI19: 2.7 | AJ19: 2.7 | AK19: 2.7 | AL19: 2.7 | AM19: =SUM(AI19:AL19) -> 10.8 | AN19: 2.7 | AO19: 2.7 | AP19: 2.7 | AQ19: 2.7 | AR19: =SUM(AN19:AQ19) -> 10.8
B20: CRE Lending Availability Index — Downside | E20: 1.5 | F20: 1.5 | G20: 1.5 | H20: 1.5 | I20: =SUM(E20:H20) -> 6 | J20: 1.6 | K20: 1.6 | L20: 1.6 | M20: 1.6 | N20: =SUM(J20:M20) -> 6.4 | O20: 1.4 | P20: 1.4 | Q20: 1.4 | R20: 1.4 | S20: =SUM(O20:R20) -> 5.6 | T20: 1.2 | U20: 1.2 | V20: 1.2 | W20: 1.2 | X20: =SUM(T20:W20) -> 4.8 | Y20: 1.4 | Z20: 1.4 | AA20: 1.4 | AB20: 1.4 | AC20: =SUM(Y20:AB20) -> 5.6 | AD20: 1.6 | AE20: 1.6 | AF20: 1.6 | AG20: 1.6 | AH20: =SUM(AD20:AG20) -> 6.4 | AI20: 1.7 | AJ20: 1.7 | AK20: 1.7 | AL20: 1.7 | AM20: =SUM(AI20:AL20) -> 6.8 | AN20: 1.8 | AO20: 1.8 | AP20: 1.8 | AQ20: 1.8 | AR20: =SUM(AN20:AQ20) -> 7.2
B21: CRE Lending Availability Index — ★ ACTIVE | E21: =IF('01 Cover & Control'!$C$19="Base",E18,IF('01 Cover & Control'!$C$19="Upside",E19,E20)) -> 1.5 | F21: =IF('01 Cover & Control'!$C$19="Base",F18,IF('01 Cover & Control'!$C$19="Upside",F19,F20)) -> 1.5 | G21: =IF('01 Cover & Control'!$C$19="Base",G18,IF('01 Cover & Control'!$C$19="Upside",G19,G20)) -> 1.5 | H21: =IF('01 Cover & Control'!$C$19="Base",H18,IF('01 Cover & Control'!$C$19="Upside",H19,H20)) -> 1.5 | I21: =SUM(E21:H21) -> 6 | J21: =IF('01 Cover & Control'!$C$19="Base",J18,IF('01 Cover & Control'!$C$19="Upside",J19,J20)) -> 1.6 | K21: =IF('01 Cover & Control'!$C$19="Base",K18,IF('01 Cover & Control'!$C$19="Upside",K19,K20)) -> 1.6 | L21: =IF('01 Cover & Control'!$C$19="Base",L18,IF('01 Cover & Control'!$C$19="Upside",L19,L20)) -> 1.6 | M21: =IF('01 Cover & Control'!$C$19="Base",M18,IF('01 Cover & Control'!$C$19="Upside",M19,M20)) -> 1.6 | N21: =SUM(J21:M21) -> 6.4 | O21: =IF('01 Cover & Control'!$C$19="Base",O18,IF('01 Cover & Control'!$C$19="Upside",O19,O20)) -> 1.8 | P21: =IF('01 Cover & Control'!$C$19="Base",P18,IF('01 Cover & Control'!$C$19="Upside",P19,P20)) -> 1.8 | Q21: =IF('01 Cover & Control'!$C$19="Base",Q18,IF('01 Cover & Control'!$C$19="Upside",Q19,Q20)) -> 1.8 | R21: =IF('01 Cover & Control'!$C$19="Base",R18,IF('01 Cover & Control'!$C$19="Upside",R19,R20)) -> 1.8 | S21: =SUM(O21:R21) -> 7.2 | T21: =IF('01 Cover & Control'!$C$19="Base",T18,IF('01 Cover & Control'!$C$19="Upside",T19,T20)) -> 2 | U21: =IF('01 Cover & Control'!$C$19="Base",U18,IF('01 Cover & Control'!$C$19="Upside",U19,U20)) -> 2 | V21: =IF('01 Cover & Control'!$C$19="Base",V18,IF('01 Cover & Control'!$C$19="Upside",V19,V20)) -> 2 | W21: =IF('01 Cover & Control'!$C$19="Base",W18,IF('01 Cover & Control'!$C$19="Upside",W19,W20)) -> 2 | X21: =SUM(T21:W21) -> 8 | Y21: =IF('01 Cover & Control'!$C$19="Base",Y18,IF('01 Cover & Control'!$C$19="Upside",Y19,Y20)) -> 2.1 | Z21: =IF('01 Cover & Control'!$C$19="Base",Z18,IF('01 Cover & Control'!$C$19="Upside",Z19,Z20)) -> 2.1 | AA21: =IF('01 Cover & Control'!$C$19="Base",AA18,IF('01 Cover & Control'!$C$19="Upside",AA19,AA20)) -> 2.1 | AB21: =IF('01 Cover & Control'!$C$19="Base",AB18,IF('01 Cover & Control'!$C$19="Upside",AB19,AB20)) -> 2.1 | AC21: =SUM(Y21:AB21) -> 8.4 | AD21: =IF('01 Cover & Control'!$C$19="Base",AD18,IF('01 Cover & Control'!$C$19="Upside",AD19,AD20)) -> 2.2 | AE21: =IF('01 Cover & Control'!$C$19="Base",AE18,IF('01 Cover & Control'!$C$19="Upside",AE19,AE20)) -> 2.2 | AF21: =IF('01 Cover & Control'!$C$19="Base",AF18,IF('01 Cover & Control'!$C$19="Upside",AF19,AF20)) -> 2.2 | AG21: =IF('01 Cover & Control'!$C$19="Base",AG18,IF('01 Cover & Control'!$C$19="Upside",AG19,AG20)) -> 2.2 | AH21: =SUM(AD21:AG21) -> 8.8 | AI21: =IF('01 Cover & Control'!$C$19="Base",AI18,IF('01 Cover & Control'!$C$19="Upside",AI19,AI20)) -> 2.2 | AJ21: =IF('01 Cover & Control'!$C$19="Base",AJ18,IF('01 Cover & Control'!$C$19="Upside",AJ19,AJ20)) -> 2.2 | AK21: =IF('01 Cover & Control'!$C$19="Base",AK18,IF('01 Cover & Control'!$C$19="Upside",AK19,AK20)) -> 2.2 | AL21: =IF('01 Cover & Control'!$C$19="Base",AL18,IF('01 Cover & Control'!$C$19="Upside",AL19,AL20)) -> 2.2 | AM21: =SUM(AI21:AL21) -> 8.8 | AN21: =IF('01 Cover & Control'!$C$19="Base",AN18,IF('01 Cover & Control'!$C$19="Upside",AN19,AN20)) -> 2.2 | AO21: =IF('01 Cover & Control'!$C$19="Base",AO18,IF('01 Cover & Control'!$C$19="Upside",AO19,AO20)) -> 2.2 | AP21: =IF('01 Cover & Control'!$C$19="Base",AP18,IF('01 Cover & Control'!$C$19="Upside",AP19,AP20)) -> 2.2 | AQ21: =IF('01 Cover & Control'!$C$19="Base",AQ18,IF('01 Cover & Control'!$C$19="Upside",AQ19,AQ20)) -> 2.2 | AR21: =SUM(AN21:AQ21) -> 8.8
B23: Cap Rate — Blended CRE (Market Average) — Base | C23: % | D23: CBRE Cap Rate Survey; NCREIF; RCA/MSCI | E23: 6.2 | F23: 6.2 | G23: 6.2 | H23: 6.2 | I23: =SUM(E23:H23) -> 24.8 | J23: 6.5 | K23: 6.5 | L23: 6.5 | M23: 6.5 | N23: =SUM(J23:M23) -> 26 | O23: 6.4 | P23: 6.4 | Q23: 6.4 | R23: 6.4 | S23: =SUM(O23:R23) -> 25.6 | T23: 6.2 | U23: 6.2 | V23: 6.2 | W23: 6.2 | X23: =SUM(T23:W23) -> 24.8 | Y23: 6.1 | Z23: 6.1 | AA23: 6.1 | AB23: 6.1 | AC23: =SUM(Y23:AB23) -> 24.4 | AD23: 6 | AE23: 6 | AF23: 6 | AG23: 6 | AH23: =SUM(AD23:AG23) -> 24 | AI23: 6 | AJ23: 6 | AK23: 6 | AL23: 6 | AM23: =SUM(AI23:AL23) -> 24 | AN23: 6 | AO23: 6 | AP23: 6 | AQ23: 6 | AR23: =SUM(AN23:AQ23) -> 24
B24: Cap Rate — Blended CRE (Market Average) — Upside | E24: 6.2 | F24: 6.2 | G24: 6.2 | H24: 6.2 | I24: =SUM(E24:H24) -> 24.8 | J24: 6.5 | K24: 6.5 | L24: 6.5 | M24: 6.5 | N24: =SUM(J24:M24) -> 26 | O24: 6.2 | P24: 6.2 | Q24: 6.2 | R24: 6.2 | S24: =SUM(O24:R24) -> 24.8 | T24: 5.9 | U24: 5.9 | V24: 5.9 | W24: 5.9 | X24: =SUM(T24:W24) -> 23.6 | Y24: 5.7 | Z24: 5.7 | AA24: 5.7 | AB24: 5.7 | AC24: =SUM(Y24:AB24) -> 22.8 | AD24: 5.6 | AE24: 5.6 | AF24: 5.6 | AG24: 5.6 | AH24: =SUM(AD24:AG24) -> 22.4 | AI24: 5.5 | AJ24: 5.5 | AK24: 5.5 | AL24: 5.5 | AM24: =SUM(AI24:AL24) -> 22 | AN24: 5.5 | AO24: 5.5 | AP24: 5.5 | AQ24: 5.5 | AR24: =SUM(AN24:AQ24) -> 22
B25: Cap Rate — Blended CRE (Market Average) — Downside | E25: 6.2 | F25: 6.2 | G25: 6.2 | H25: 6.2 | I25: =SUM(E25:H25) -> 24.8 | J25: 6.5 | K25: 6.5 | L25: 6.5 | M25: 6.5 | N25: =SUM(J25:M25) -> 26 | O25: 6.8 | P25: 6.8 | Q25: 6.8 | R25: 6.8 | S25: =SUM(O25:R25) -> 27.2 | T25: 7.1 | U25: 7.1 | V25: 7.1 | W25: 7.1 | X25: =SUM(T25:W25) -> 28.4 | Y25: 7 | Z25: 7 | AA25: 7 | AB25: 7 | AC25: =SUM(Y25:AB25) -> 28 | AD25: 6.9 | AE25: 6.9 | AF25: 6.9 | AG25: 6.9 | AH25: =SUM(AD25:AG25) -> 27.6 | AI25: 6.8 | AJ25: 6.8 | AK25: 6.8 | AL25: 6.8 | AM25: =SUM(AI25:AL25) -> 27.2 | AN25: 6.7 | AO25: 6.7 | AP25: 6.7 | AQ25: 6.7 | AR25: =SUM(AN25:AQ25) -> 26.8
B26: Cap Rate — Blended CRE (Market Average) — ★ ACTIVE | E26: =IF('01 Cover & Control'!$C$19="Base",E23,IF('01 Cover & Control'!$C$19="Upside",E24,E25)) -> 6.2 | F26: =IF('01 Cover & Control'!$C$19="Base",F23,IF('01 Cover & Control'!$C$19="Upside",F24,F25)) -> 6.2 | G26: =IF('01 Cover & Control'!$C$19="Base",G23,IF('01 Cover & Control'!$C$19="Upside",G24,G25)) -> 6.2 | H26: =IF('01 Cover & Control'!$C$19="Base",H23,IF('01 Cover & Control'!$C$19="Upside",H24,H25)) -> 6.2 | I26: =SUM(E26:H26) -> 24.8 | J26: =IF('01 Cover & Control'!$C$19="Base",J23,IF('01 Cover & Control'!$C$19="Upside",J24,J25)) -> 6.5 | K26: =IF('01 Cover & Control'!$C$19="Base",K23,IF('01 Cover & Control'!$C$19="Upside",K24,K25)) -> 6.5 | L26: =IF('01 Cover & Control'!$C$19="Base",L23,IF('01 Cover & Control'!$C$19="Upside",L24,L25)) -> 6.5 | M26: =IF('01 Cover & Control'!$C$19="Base",M23,IF('01 Cover & Control'!$C$19="Upside",M24,M25)) -> 6.5 | N26: =SUM(J26:M26) -> 26 | O26: =IF('01 Cover & Control'!$C$19="Base",O23,IF('01 Cover & Control'!$C$19="Upside",O24,O25)) -> 6.4 | P26: =IF('01 Cover & Control'!$C$19="Base",P23,IF('01 Cover & Control'!$C$19="Upside",P24,P25)) -> 6.4 | Q26: =IF('01 Cover & Control'!$C$19="Base",Q23,IF('01 Cover & Control'!$C$19="Upside",Q24,Q25)) -> 6.4 | R26: =IF('01 Cover & Control'!$C$19="Base",R23,IF('01 Cover & Control'!$C$19="Upside",R24,R25)) -> 6.4 | S26: =SUM(O26:R26) -> 25.6 | T26: =IF('01 Cover & Control'!$C$19="Base",T23,IF('01 Cover & Control'!$C$19="Upside",T24,T25)) -> 6.2 | U26: =IF('01 Cover & Control'!$C$19="Base",U23,IF('01 Cover & Control'!$C$19="Upside",U24,U25)) -> 6.2 | V26: =IF('01 Cover & Control'!$C$19="Base",V23,IF('01 Cover & Control'!$C$19="Upside",V24,V25)) -> 6.2 | W26: =IF('01 Cover & Control'!$C$19="Base",W23,IF('01 Cover & Control'!$C$19="Upside",W24,W25)) -> 6.2 | X26: =SUM(T26:W26) -> 24.8 | Y26: =IF('01 Cover & Control'!$C$19="Base",Y23,IF('01 Cover & Control'!$C$19="Upside",Y24,Y25)) -> 6.1 | Z26: =IF('01 Cover & Control'!$C$19="Base",Z23,IF('01 Cover & Control'!$C$19="Upside",Z24,Z25)) -> 6.1 | AA26: =IF('01 Cover & Control'!$C$19="Base",AA23,IF('01 Cover & Control'!$C$19="Upside",AA24,AA25)) -> 6.1 | AB26: =IF('01 Cover & Control'!$C$19="Base",AB23,IF('01 Cover & Control'!$C$19="Upside",AB24,AB25)) -> 6.1 | AC26: =SUM(Y26:AB26) -> 24.4 | AD26: =IF('01 Cover & Control'!$C$19="Base",AD23,IF('01 Cover & Control'!$C$19="Upside",AD24,AD25)) -> 6 | AE26: =IF('01 Cover & Control'!$C$19="Base",AE23,IF('01 Cover & Control'!$C$19="Upside",AE24,AE25)) -> 6 | AF26: =IF('01 Cover & Control'!$C$19="Base",AF23,IF('01 Cover & Control'!$C$19="Upside",AF24,AF25)) -> 6 | AG26: =IF('01 Cover & Control'!$C$19="Base",AG23,IF('01 Cover & Control'!$C$19="Upside",AG24,AG25)) -> 6 | AH26: =SUM(AD26:AG26) -> 24 | AI26: =IF('01 Cover & Control'!$C$19="Base",AI23,IF('01 Cover & Control'!$C$19="Upside",AI24,AI25)) -> 6 | AJ26: =IF('01 Cover & Control'!$C$19="Base",AJ23,IF('01 Cover & Control'!$C$19="Upside",AJ24,AJ25)) -> 6 | AK26: =IF('01 Cover & Control'!$C$19="Base",AK23,IF('01 Cover & Control'!$C$19="Upside",AK24,AK25)) -> 6 | AL26: =IF('01 Cover & Control'!$C$19="Base",AL23,IF('01 Cover & Control'!$C$19="Upside",AL24,AL25)) -> 6 | AM26: =SUM(AI26:AL26) -> 24 | AN26: =IF('01 Cover & Control'!$C$19="Base",AN23,IF('01 Cover & Control'!$C$19="Upside",AN24,AN25)) -> 6 | AO26: =IF('01 Cover & Control'!$C$19="Base",AO23,IF('01 Cover & Control'!$C$19="Upside",AO24,AO25)) -> 6 | AP26: =IF('01 Cover & Control'!$C$19="Base",AP23,IF('01 Cover & Control'!$C$19="Upside",AP24,AP25)) -> 6 | AQ26: =IF('01 Cover & Control'!$C$19="Base",AQ23,IF('01 Cover & Control'!$C$19="Upside",AQ24,AQ25)) -> 6 | AR26: =SUM(AN26:AQ26) -> 24
B28: Market Rent Growth — National Blended — Base | C28: % / yr | D28: CBRE MarketView; JLL Research; Cushman & Wakefield | E28: 2.5 | F28: 2.5 | G28: 2.5 | H28: 2.5 | I28: =SUM(E28:H28) -> 10 | J28: 2 | K28: 2 | L28: 2 | M28: 2 | N28: =SUM(J28:M28) -> 8 | O28: 2.2 | P28: 2.2 | Q28: 2.2 | R28: 2.2 | S28: =SUM(O28:R28) -> 8.8 | T28: 2.8 | U28: 2.8 | V28: 2.8 | W28: 2.8 | X28: =SUM(T28:W28) -> 11.2 | Y28: 3 | Z28: 3 | AA28: 3 | AB28: 3 | AC28: =SUM(Y28:AB28) -> 12 | AD28: 3 | AE28: 3 | AF28: 3 | AG28: 3 | AH28: =SUM(AD28:AG28) -> 12 | AI28: 3 | AJ28: 3 | AK28: 3 | AL28: 3 | AM28: =SUM(AI28:AL28) -> 12 | AN28: 3 | AO28: 3 | AP28: 3 | AQ28: 3 | AR28: =SUM(AN28:AQ28) -> 12
B29: Market Rent Growth — National Blended — Upside | E29: 2.5 | F29: 2.5 | G29: 2.5 | H29: 2.5 | I29: =SUM(E29:H29) -> 10 | J29: 2 | K29: 2 | L29: 2 | M29: 2 | N29: =SUM(J29:M29) -> 8 | O29: 2.8 | P29: 2.8 | Q29: 2.8 | R29: 2.8 | S29: =SUM(O29:R29) -> 11.2 | T29: 3.6 | U29: 3.6 | V29: 3.6 | W29: 3.6 | X29: =SUM(T29:W29) -> 14.4 | Y29: 3.8 | Z29: 3.8 | AA29: 3.8 | AB29: 3.8 | AC29: =SUM(Y29:AB29) -> 15.2 | AD29: 3.8 | AE29: 3.8 | AF29: 3.8 | AG29: 3.8 | AH29: =SUM(AD29:AG29) -> 15.2 | AI29: 3.7 | AJ29: 3.7 | AK29: 3.7 | AL29: 3.7 | AM29: =SUM(AI29:AL29) -> 14.8 | AN29: 3.6 | AO29: 3.6 | AP29: 3.6 | AQ29: 3.6 | AR29: =SUM(AN29:AQ29) -> 14.4
B30: Market Rent Growth — National Blended — Downside | E30: 2.5 | F30: 2.5 | G30: 2.5 | H30: 2.5 | I30: =SUM(E30:H30) -> 10 | J30: 2 | K30: 2 | L30: 2 | M30: 2 | N30: =SUM(J30:M30) -> 8 | O30: 1 | P30: 1 | Q30: 1 | R30: 1 | S30: =SUM(O30:R30) -> 4 | T30: 0.5 | U30: 0.5 | V30: 0.5 | W30: 0.5 | X30: =SUM(T30:W30) -> 2 | Y30: 1 | Z30: 1 | AA30: 1 | AB30: 1 | AC30: =SUM(Y30:AB30) -> 4 | AD30: 1.5 | AE30: 1.5 | AF30: 1.5 | AG30: 1.5 | AH30: =SUM(AD30:AG30) -> 6 | AI30: 1.8 | AJ30: 1.8 | AK30: 1.8 | AL30: 1.8 | AM30: =SUM(AI30:AL30) -> 7.2 | AN30: 2 | AO30: 2 | AP30: 2 | AQ30: 2 | AR30: =SUM(AN30:AQ30) -> 8
B31: Market Rent Growth — National Blended — ★ ACTIVE | E31: =IF('01 Cover & Control'!$C$19="Base",E28,IF('01 Cover & Control'!$C$19="Upside",E29,E30)) -> 2.5 | F31: =IF('01 Cover & Control'!$C$19="Base",F28,IF('01 Cover & Control'!$C$19="Upside",F29,F30)) -> 2.5 | G31: =IF('01 Cover & Control'!$C$19="Base",G28,IF('01 Cover & Control'!$C$19="Upside",G29,G30)) -> 2.5 | H31: =IF('01 Cover & Control'!$C$19="Base",H28,IF('01 Cover & Control'!$C$19="Upside",H29,H30)) -> 2.5 | I31: =SUM(E31:H31) -> 10 | J31: =IF('01 Cover & Control'!$C$19="Base",J28,IF('01 Cover & Control'!$C$19="Upside",J29,J30)) -> 2 | K31: =IF('01 Cover & Control'!$C$19="Base",K28,IF('01 Cover & Control'!$C$19="Upside",K29,K30)) -> 2 | L31: =IF('01 Cover & Control'!$C$19="Base",L28,IF('01 Cover & Control'!$C$19="Upside",L29,L30)) -> 2 | M31: =IF('01 Cover & Control'!$C$19="Base",M28,IF('01 Cover & Control'!$C$19="Upside",M29,M30)) -> 2 | N31: =SUM(J31:M31) -> 8 | O31: =IF('01 Cover & Control'!$C$19="Base",O28,IF('01 Cover & Control'!$C$19="Upside",O29,O30)) -> 2.2 | P31: =IF('01 Cover & Control'!$C$19="Base",P28,IF('01 Cover & Control'!$C$19="Upside",P29,P30)) -> 2.2 | Q31: =IF('01 Cover & Control'!$C$19="Base",Q28,IF('01 Cover & Control'!$C$19="Upside",Q29,Q30)) -> 2.2 | R31: =IF('01 Cover & Control'!$C$19="Base",R28,IF('01 Cover & Control'!$C$19="Upside",R29,R30)) -> 2.2 | S31: =SUM(O31:R31) -> 8.8 | T31: =IF('01 Cover & Control'!$C$19="Base",T28,IF('01 Cover & Control'!$C$19="Upside",T29,T30)) -> 2.8 | U31: =IF('01 Cover & Control'!$C$19="Base",U28,IF('01 Cover & Control'!$C$19="Upside",U29,U30)) -> 2.8 | V31: =IF('01 Cover & Control'!$C$19="Base",V28,IF('01 Cover & Control'!$C$19="Upside",V29,V30)) -> 2.8 | W31: =IF('01 Cover & Control'!$C$19="Base",W28,IF('01 Cover & Control'!$C$19="Upside",W29,W30)) -> 2.8 | X31: =SUM(T31:W31) -> 11.2 | Y31: =IF('01 Cover & Control'!$C$19="Base",Y28,IF('01 Cover & Control'!$C$19="Upside",Y29,Y30)) -> 3 | Z31: =IF('01 Cover & Control'!$C$19="Base",Z28,IF('01 Cover & Control'!$C$19="Upside",Z29,Z30)) -> 3 | AA31: =IF('01 Cover & Control'!$C$19="Base",AA28,IF('01 Cover & Control'!$C$19="Upside",AA29,AA30)) -> 3 | AB31: =IF('01 Cover & Control'!$C$19="Base",AB28,IF('01 Cover & Control'!$C$19="Upside",AB29,AB30)) -> 3 | AC31: =SUM(Y31:AB31) -> 12 | AD31: =IF('01 Cover & Control'!$C$19="Base",AD28,IF('01 Cover & Control'!$C$19="Upside",AD29,AD30)) -> 3 | AE31: =IF('01 Cover & Control'!$C$19="Base",AE28,IF('01 Cover & Control'!$C$19="Upside",AE29,AE30)) -> 3 | AF31: =IF('01 Cover & Control'!$C$19="Base",AF28,IF('01 Cover & Control'!$C$19="Upside",AF29,AF30)) -> 3 | AG31: =IF('01 Cover & Control'!$C$19="Base",AG28,IF('01 Cover & Control'!$C$19="Upside",AG29,AG30)) -> 3 | AH31: =SUM(AD31:AG31) -> 12 | AI31: =IF('01 Cover & Control'!$C$19="Base",AI28,IF('01 Cover & Control'!$C$19="Upside",AI29,AI30)) -> 3 | AJ31: =IF('01 Cover & Control'!$C$19="Base",AJ28,IF('01 Cover & Control'!$C$19="Upside",AJ29,AJ30)) -> 3 | AK31: =IF('01 Cover & Control'!$C$19="Base",AK28,IF('01 Cover & Control'!$C$19="Upside",AK29,AK30)) -> 3 | AL31: =IF('01 Cover & Control'!$C$19="Base",AL28,IF('01 Cover & Control'!$C$19="Upside",AL29,AL30)) -> 3 | AM31: =SUM(AI31:AL31) -> 12 | AN31: =IF('01 Cover & Control'!$C$19="Base",AN28,IF('01 Cover & Control'!$C$19="Upside",AN29,AN30)) -> 3 | AO31: =IF('01 Cover & Control'!$C$19="Base",AO28,IF('01 Cover & Control'!$C$19="Upside",AO29,AO30)) -> 3 | AP31: =IF('01 Cover & Control'!$C$19="Base",AP28,IF('01 Cover & Control'!$C$19="Upside",AP29,AP30)) -> 3 | AQ31: =IF('01 Cover & Control'!$C$19="Base",AQ28,IF('01 Cover & Control'!$C$19="Upside",AQ29,AQ30)) -> 3 | AR31: =SUM(AN31:AQ31) -> 12
B33: Inflation / CPI (YoY) — Base | C33: % / yr | D33: BLS CPI Release; Federal Reserve PCE | E33: 4.1 | F33: 4.1 | G33: 4.1 | H33: 4.1 | I33: =SUM(E33:H33) -> 16.4 | J33: 3.2 | K33: 3.2 | L33: 3.2 | M33: 3.2 | N33: =SUM(J33:M33) -> 12.8 | O33: 2.6 | P33: 2.6 | Q33: 2.6 | R33: 2.6 | S33: =SUM(O33:R33) -> 10.4 | T33: 2.3 | U33: 2.3 | V33: 2.3 | W33: 2.3 | X33: =SUM(T33:W33) -> 9.2 | Y33: 2.2 | Z33: 2.2 | AA33: 2.2 | AB33: 2.2 | AC33: =SUM(Y33:AB33) -> 8.8 | AD33: 2.1 | AE33: 2.1 | AF33: 2.1 | AG33: 2.1 | AH33: =SUM(AD33:AG33) -> 8.4 | AI33: 2 | AJ33: 2 | AK33: 2 | AL33: 2 | AM33: =SUM(AI33:AL33) -> 8 | AN33: 2 | AO33: 2 | AP33: 2 | AQ33: 2 | AR33: =SUM(AN33:AQ33) -> 8
B34: Inflation / CPI (YoY) — Upside | E34: 4.1 | F34: 4.1 | G34: 4.1 | H34: 4.1 | I34: =SUM(E34:H34) -> 16.4 | J34: 3.2 | K34: 3.2 | L34: 3.2 | M34: 3.2 | N34: =SUM(J34:M34) -> 12.8 | O34: 2.4 | P34: 2.4 | Q34: 2.4 | R34: 2.4 | S34: =SUM(O34:R34) -> 9.6 | T34: 2.1 | U34: 2.1 | V34: 2.1 | W34: 2.1 | X34: =SUM(T34:W34) -> 8.4 | Y34: 2 | Z34: 2 | AA34: 2 | AB34: 2 | AC34: =SUM(Y34:AB34) -> 8 | AD34: 2 | AE34: 2 | AF34: 2 | AG34: 2 | AH34: =SUM(AD34:AG34) -> 8 | AI34: 2 | AJ34: 2 | AK34: 2 | AL34: 2 | AM34: =SUM(AI34:AL34) -> 8 | AN34: 2 | AO34: 2 | AP34: 2 | AQ34: 2 | AR34: =SUM(AN34:AQ34) -> 8
B35: Inflation / CPI (YoY) — Downside | E35: 4.1 | F35: 4.1 | G35: 4.1 | H35: 4.1 | I35: =SUM(E35:H35) -> 16.4 | J35: 3.2 | K35: 3.2 | L35: 3.2 | M35: 3.2 | N35: =SUM(J35:M35) -> 12.8 | O35: 3 | P35: 3 | Q35: 3 | R35: 3 | S35: =SUM(O35:R35) -> 12 | T35: 3.2 | U35: 3.2 | V35: 3.2 | W35: 3.2 | X35: =SUM(T35:W35) -> 12.8 | Y35: 3 | Z35: 3 | AA35: 3 | AB35: 3 | AC35: =SUM(Y35:AB35) -> 12 | AD35: 2.8 | AE35: 2.8 | AF35: 2.8 | AG35: 2.8 | AH35: =SUM(AD35:AG35) -> 11.2 | AI35: 2.6 | AJ35: 2.6 | AK35: 2.6 | AL35: 2.6 | AM35: =SUM(AI35:AL35) -> 10.4 | AN35: 2.5 | AO35: 2.5 | AP35: 2.5 | AQ35: 2.5 | AR35: =SUM(AN35:AQ35) -> 10
B36: Inflation / CPI (YoY) — ★ ACTIVE | E36: =IF('01 Cover & Control'!$C$19="Base",E33,IF('01 Cover & Control'!$C$19="Upside",E34,E35)) -> 4.1 | F36: =IF('01 Cover & Control'!$C$19="Base",F33,IF('01 Cover & Control'!$C$19="Upside",F34,F35)) -> 4.1 | G36: =IF('01 Cover & Control'!$C$19="Base",G33,IF('01 Cover & Control'!$C$19="Upside",G34,G35)) -> 4.1 | H36: =IF('01 Cover & Control'!$C$19="Base",H33,IF('01 Cover & Control'!$C$19="Upside",H34,H35)) -> 4.1 | I36: =SUM(E36:H36) -> 16.4 | J36: =IF('01 Cover & Control'!$C$19="Base",J33,IF('01 Cover & Control'!$C$19="Upside",J34,J35)) -> 3.2 | K36: =IF('01 Cover & Control'!$C$19="Base",K33,IF('01 Cover & Control'!$C$19="Upside",K34,K35)) -> 3.2 | L36: =IF('01 Cover & Control'!$C$19="Base",L33,IF('01 Cover & Control'!$C$19="Upside",L34,L35)) -> 3.2 | M36: =IF('01 Cover & Control'!$C$19="Base",M33,IF('01 Cover & Control'!$C$19="Upside",M34,M35)) -> 3.2 | N36: =SUM(J36:M36) -> 12.8 | O36: =IF('01 Cover & Control'!$C$19="Base",O33,IF('01 Cover & Control'!$C$19="Upside",O34,O35)) -> 2.6 | P36: =IF('01 Cover & Control'!$C$19="Base",P33,IF('01 Cover & Control'!$C$19="Upside",P34,P35)) -> 2.6 | Q36: =IF('01 Cover & Control'!$C$19="Base",Q33,IF('01 Cover & Control'!$C$19="Upside",Q34,Q35)) -> 2.6 | R36: =IF('01 Cover & Control'!$C$19="Base",R33,IF('01 Cover & Control'!$C$19="Upside",R34,R35)) -> 2.6 | S36: =SUM(O36:R36) -> 10.4 | T36: =IF('01 Cover & Control'!$C$19="Base",T33,IF('01 Cover & Control'!$C$19="Upside",T34,T35)) -> 2.3 | U36: =IF('01 Cover & Control'!$C$19="Base",U33,IF('01 Cover & Control'!$C$19="Upside",U34,U35)) -> 2.3 | V36: =IF('01 Cover & Control'!$C$19="Base",V33,IF('01 Cover & Control'!$C$19="Upside",V34,V35)) -> 2.3 | W36: =IF('01 Cover & Control'!$C$19="Base",W33,IF('01 Cover & Control'!$C$19="Upside",W34,W35)) -> 2.3 | X36: =SUM(T36:W36) -> 9.2 | Y36: =IF('01 Cover & Control'!$C$19="Base",Y33,IF('01 Cover & Control'!$C$19="Upside",Y34,Y35)) -> 2.2 | Z36: =IF('01 Cover & Control'!$C$19="Base",Z33,IF('01 Cover & Control'!$C$19="Upside",Z34,Z35)) -> 2.2 | AA36: =IF('01 Cover & Control'!$C$19="Base",AA33,IF('01 Cover & Control'!$C$19="Upside",AA34,AA35)) -> 2.2 | AB36: =IF('01 Cover & Control'!$C$19="Base",AB33,IF('01 Cover & Control'!$C$19="Upside",AB34,AB35)) -> 2.2 | AC36: =SUM(Y36:AB36) -> 8.8 | AD36: =IF('01 Cover & Control'!$C$19="Base",AD33,IF('01 Cover & Control'!$C$19="Upside",AD34,AD35)) -> 2.1 | AE36: =IF('01 Cover & Control'!$C$19="Base",AE33,IF('01 Cover & Control'!$C$19="Upside",AE34,AE35)) -> 2.1 | AF36: =IF('01 Cover & Control'!$C$19="Base",AF33,IF('01 Cover & Control'!$C$19="Upside",AF34,AF35)) -> 2.1 | AG36: =IF('01 Cover & Control'!$C$19="Base",AG33,IF('01 Cover & Control'!$C$19="Upside",AG34,AG35)) -> 2.1 | AH36: =SUM(AD36:AG36) -> 8.4 | AI36: =IF('01 Cover & Control'!$C$19="Base",AI33,IF('01 Cover & Control'!$C$19="Upside",AI34,AI35)) -> 2 | AJ36: =IF('01 Cover & Control'!$C$19="Base",AJ33,IF('01 Cover & Control'!$C$19="Upside",AJ34,AJ35)) -> 2 | AK36: =IF('01 Cover & Control'!$C$19="Base",AK33,IF('01 Cover & Control'!$C$19="Upside",AK34,AK35)) -> 2 | AL36: =IF('01 Cover & Control'!$C$19="Base",AL33,IF('01 Cover & Control'!$C$19="Upside",AL34,AL35)) -> 2 | AM36: =SUM(AI36:AL36) -> 8 | AN36: =IF('01 Cover & Control'!$C$19="Base",AN33,IF('01 Cover & Control'!$C$19="Upside",AN34,AN35)) -> 2 | AO36: =IF('01 Cover & Control'!$C$19="Base",AO33,IF('01 Cover & Control'!$C$19="Upside",AO34,AO35)) -> 2 | AP36: =IF('01 Cover & Control'!$C$19="Base",AP33,IF('01 Cover & Control'!$C$19="Upside",AP34,AP35)) -> 2 | AQ36: =IF('01 Cover & Control'!$C$19="Base",AQ33,IF('01 Cover & Control'!$C$19="Upside",AQ34,AQ35)) -> 2 | AR36: =SUM(AN36:AQ36) -> 8
B38: Wage Growth — National Average (YoY) — Base | C38: % / yr | D38: BLS Employment Cost Index; ADP Workforce Vitality Report | E38: 4.4 | F38: 4.4 | G38: 4.4 | H38: 4.4 | I38: =SUM(E38:H38) -> 17.6 | J38: 4 | K38: 4 | L38: 4 | M38: 4 | N38: =SUM(J38:M38) -> 16 | O38: 3.6 | P38: 3.6 | Q38: 3.6 | R38: 3.6 | S38: =SUM(O38:R38) -> 14.4 | T38: 3.4 | U38: 3.4 | V38: 3.4 | W38: 3.4 | X38: =SUM(T38:W38) -> 13.6 | Y38: 3.3 | Z38: 3.3 | AA38: 3.3 | AB38: 3.3 | AC38: =SUM(Y38:AB38) -> 13.2 | AD38: 3.2 | AE38: 3.2 | AF38: 3.2 | AG38: 3.2 | AH38: =SUM(AD38:AG38) -> 12.8 | AI38: 3.2 | AJ38: 3.2 | AK38: 3.2 | AL38: 3.2 | AM38: =SUM(AI38:AL38) -> 12.8 | AN38: 3.2 | AO38: 3.2 | AP38: 3.2 | AQ38: 3.2 | AR38: =SUM(AN38:AQ38) -> 12.8
B39: Wage Growth — National Average (YoY) — Upside | E39: 4.4 | F39: 4.4 | G39: 4.4 | H39: 4.4 | I39: =SUM(E39:H39) -> 17.6 | J39: 4 | K39: 4 | L39: 4 | M39: 4 | N39: =SUM(J39:M39) -> 16 | O39: 3.8 | P39: 3.8 | Q39: 3.8 | R39: 3.8 | S39: =SUM(O39:R39) -> 15.2 | T39: 3.7 | U39: 3.7 | V39: 3.7 | W39: 3.7 | X39: =SUM(T39:W39) -> 14.8 | Y39: 3.6 | Z39: 3.6 | AA39: 3.6 | AB39: 3.6 | AC39: =SUM(Y39:AB39) -> 14.4 | AD39: 3.5 | AE39: 3.5 | AF39: 3.5 | AG39: 3.5 | AH39: =SUM(AD39:AG39) -> 14 | AI39: 3.4 | AJ39: 3.4 | AK39: 3.4 | AL39: 3.4 | AM39: =SUM(AI39:AL39) -> 13.6 | AN39: 3.4 | AO39: 3.4 | AP39: 3.4 | AQ39: 3.4 | AR39: =SUM(AN39:AQ39) -> 13.6
B40: Wage Growth — National Average (YoY) — Downside | E40: 4.4 | F40: 4.4 | G40: 4.4 | H40: 4.4 | I40: =SUM(E40:H40) -> 17.6 | J40: 4 | K40: 4 | L40: 4 | M40: 4 | N40: =SUM(J40:M40) -> 16 | O40: 3.4 | P40: 3.4 | Q40: 3.4 | R40: 3.4 | S40: =SUM(O40:R40) -> 13.6 | T40: 3.2 | U40: 3.2 | V40: 3.2 | W40: 3.2 | X40: =SUM(T40:W40) -> 12.8 | Y40: 3 | Z40: 3 | AA40: 3 | AB40: 3 | AC40: =SUM(Y40:AB40) -> 12 | AD40: 2.9 | AE40: 2.9 | AF40: 2.9 | AG40: 2.9 | AH40: =SUM(AD40:AG40) -> 11.6 | AI40: 2.8 | AJ40: 2.8 | AK40: 2.8 | AL40: 2.8 | AM40: =SUM(AI40:AL40) -> 11.2 | AN40: 2.8 | AO40: 2.8 | AP40: 2.8 | AQ40: 2.8 | AR40: =SUM(AN40:AQ40) -> 11.2
B41: Wage Growth — National Average (YoY) — ★ ACTIVE | E41: =IF('01 Cover & Control'!$C$19="Base",E38,IF('01 Cover & Control'!$C$19="Upside",E39,E40)) -> 4.4 | F41: =IF('01 Cover & Control'!$C$19="Base",F38,IF('01 Cover & Control'!$C$19="Upside",F39,F40)) -> 4.4 | G41: =IF('01 Cover & Control'!$C$19="Base",G38,IF('01 Cover & Control'!$C$19="Upside",G39,G40)) -> 4.4 | H41: =IF('01 Cover & Control'!$C$19="Base",H38,IF('01 Cover & Control'!$C$19="Upside",H39,H40)) -> 4.4 | I41: =SUM(E41:H41) -> 17.6 | J41: =IF('01 Cover & Control'!$C$19="Base",J38,IF('01 Cover & Control'!$C$19="Upside",J39,J40)) -> 4 | K41: =IF('01 Cover & Control'!$C$19="Base",K38,IF('01 Cover & Control'!$C$19="Upside",K39,K40)) -> 4 | L41: =IF('01 Cover & Control'!$C$19="Base",L38,IF('01 Cover & Control'!$C$19="Upside",L39,L40)) -> 4 | M41: =IF('01 Cover & Control'!$C$19="Base",M38,IF('01 Cover & Control'!$C$19="Upside",M39,M40)) -> 4 | N41: =SUM(J41:M41) -> 16 | O41: =IF('01 Cover & Control'!$C$19="Base",O38,IF('01 Cover & Control'!$C$19="Upside",O39,O40)) -> 3.6 | P41: =IF('01 Cover & Control'!$C$19="Base",P38,IF('01 Cover & Control'!$C$19="Upside",P39,P40)) -> 3.6 | Q41: =IF('01 Cover & Control'!$C$19="Base",Q38,IF('01 Cover & Control'!$C$19="Upside",Q39,Q40)) -> 3.6 | R41: =IF('01 Cover & Control'!$C$19="Base",R38,IF('01 Cover & Control'!$C$19="Upside",R39,R40)) -> 3.6 | S41: =SUM(O41:R41) -> 14.4 | T41: =IF('01 Cover & Control'!$C$19="Base",T38,IF('01 Cover & Control'!$C$19="Upside",T39,T40)) -> 3.4 | U41: =IF('01 Cover & Control'!$C$19="Base",U38,IF('01 Cover & Control'!$C$19="Upside",U39,U40)) -> 3.4 | V41: =IF('01 Cover & Control'!$C$19="Base",V38,IF('01 Cover & Control'!$C$19="Upside",V39,V40)) -> 3.4 | W41: =IF('01 Cover & Control'!$C$19="Base",W38,IF('01 Cover & Control'!$C$19="Upside",W39,W40)) -> 3.4 | X41: =SUM(T41:W41) -> 13.6 | Y41: =IF('01 Cover & Control'!$C$19="Base",Y38,IF('01 Cover & Control'!$C$19="Upside",Y39,Y40)) -> 3.3 | Z41: =IF('01 Cover & Control'!$C$19="Base",Z38,IF('01 Cover & Control'!$C$19="Upside",Z39,Z40)) -> 3.3 | AA41: =IF('01 Cover & Control'!$C$19="Base",AA38,IF('01 Cover & Control'!$C$19="Upside",AA39,AA40)) -> 3.3 | AB41: =IF('01 Cover & Control'!$C$19="Base",AB38,IF('01 Cover & Control'!$C$19="Upside",AB39,AB40)) -> 3.3 | AC41: =SUM(Y41:AB41) -> 13.2 | AD41: =IF('01 Cover & Control'!$C$19="Base",AD38,IF('01 Cover & Control'!$C$19="Upside",AD39,AD40)) -> 3.2 | AE41: =IF('01 Cover & Control'!$C$19="Base",AE38,IF('01 Cover & Control'!$C$19="Upside",AE39,AE40)) -> 3.2 | AF41: =IF('01 Cover & Control'!$C$19="Base",AF38,IF('01 Cover & Control'!$C$19="Upside",AF39,AF40)) -> 3.2 | AG41: =IF('01 Cover & Control'!$C$19="Base",AG38,IF('01 Cover & Control'!$C$19="Upside",AG39,AG40)) -> 3.2 | AH41: =SUM(AD41:AG41) -> 12.8 | AI41: =IF('01 Cover & Control'!$C$19="Base",AI38,IF('01 Cover & Control'!$C$19="Upside",AI39,AI40)) -> 3.2 | AJ41: =IF('01 Cover & Control'!$C$19="Base",AJ38,IF('01 Cover & Control'!$C$19="Upside",AJ39,AJ40)) -> 3.2 | AK41: =IF('01 Cover & Control'!$C$19="Base",AK38,IF('01 Cover & Control'!$C$19="Upside",AK39,AK40)) -> 3.2 | AL41: =IF('01 Cover & Control'!$C$19="Base",AL38,IF('01 Cover & Control'!$C$19="Upside",AL39,AL40)) -> 3.2 | AM41: =SUM(AI41:AL41) -> 12.8 | AN41: =IF('01 Cover & Control'!$C$19="Base",AN38,IF('01 Cover & Control'!$C$19="Upside",AN39,AN40)) -> 3.2 | AO41: =IF('01 Cover & Control'!$C$19="Base",AO38,IF('01 Cover & Control'!$C$19="Upside",AO39,AO40)) -> 3.2 | AP41: =IF('01 Cover & Control'!$C$19="Base",AP38,IF('01 Cover & Control'!$C$19="Upside",AP39,AP40)) -> 3.2 | AQ41: =IF('01 Cover & Control'!$C$19="Base",AQ38,IF('01 Cover & Control'!$C$19="Upside",AQ39,AQ40)) -> 3.2 | AR41: =SUM(AN41:AQ41) -> 12.8
A45: SECTION B — CRE MARKET ACTIVITY
A47: B1 — INVESTMENT SALES MARKET
B49: National IS Transaction Volume — Total Market — Base | C49: $B | D49: MSCI Real Capital Analytics (RCA) Quarterly Capital Trends | E49: 78 | F49: 78 | G49: 78 | H49: 78 | I49: =SUM(E49:H49) -> 312 | J49: 82 | K49: 82 | L49: 82 | M49: 82 | N49: =SUM(J49:M49) -> 328 | O49: 92 | P49: 92 | Q49: 92 | R49: 92 | S49: =SUM(O49:R49) -> 368 | T49: 105 | U49: 105 | V49: 105 | W49: 105 | X49: =SUM(T49:W49) -> 420 | Y49: 112 | Z49: 112 | AA49: 112 | AB49: 112 | AC49: =SUM(Y49:AB49) -> 448 | AD49: 118 | AE49: 118 | AF49: 118 | AG49: 118 | AH49: =SUM(AD49:AG49) -> 472 | AI49: 122 | AJ49: 122 | AK49: 122 | AL49: 122 | AM49: =SUM(AI49:AL49) -> 488 | AN49: 126 | AO49: 126 | AP49: 126 | AQ49: 126 | AR49: =SUM(AN49:AQ49) -> 504
B50: National IS Transaction Volume — Total Market — Upside | E50: 78 | F50: 78 | G50: 78 | H50: 78 | I50: =SUM(E50:H50) -> 312 | J50: 82 | K50: 82 | L50: 82 | M50: 82 | N50: =SUM(J50:M50) -> 328 | O50: 99 | P50: 99 | Q50: 99 | R50: 99 | S50: =SUM(O50:R50) -> 396 | T50: 118 | U50: 118 | V50: 118 | W50: 118 | X50: =SUM(T50:W50) -> 472 | Y50: 126 | Z50: 126 | AA50: 126 | AB50: 126 | AC50: =SUM(Y50:AB50) -> 504 | AD50: 133 | AE50: 133 | AF50: 133 | AG50: 133 | AH50: =SUM(AD50:AG50) -> 532 | AI50: 138 | AJ50: 138 | AK50: 138 | AL50: 138 | AM50: =SUM(AI50:AL50) -> 552 | AN50: 143 | AO50: 143 | AP50: 143 | AQ50: 143 | AR50: =SUM(AN50:AQ50) -> 572
B51: National IS Transaction Volume — Total Market — Downside | E51: 78 | F51: 78 | G51: 78 | H51: 78 | I51: =SUM(E51:H51) -> 312 | J51: 82 | K51: 82 | L51: 82 | M51: 82 | N51: =SUM(J51:M51) -> 328 | O51: 86 | P51: 86 | Q51: 86 | R51: 86 | S51: =SUM(O51:R51) -> 344 | T51: 90 | U51: 90 | V51: 90 | W51: 90 | X51: =SUM(T51:W51) -> 360 | Y51: 96 | Z51: 96 | AA51: 96 | AB51: 96 | AC51: =SUM(Y51:AB51) -> 384 | AD51: 102 | AE51: 102 | AF51: 102 | AG51: 102 | AH51: =SUM(AD51:AG51) -> 408 | AI51: 107 | AJ51: 107 | AK51: 107 | AL51: 107 | AM51: =SUM(AI51:AL51) -> 428 | AN51: 112 | AO51: 112 | AP51: 112 | AQ51: 112 | AR51: =SUM(AN51:AQ51) -> 448
B52: National IS Transaction Volume — Total Market — ★ ACTIVE | E52: =IF('01 Cover & Control'!$C$19="Base",E49,IF('01 Cover & Control'!$C$19="Upside",E50,E51)) -> 78 | F52: =IF('01 Cover & Control'!$C$19="Base",F49,IF('01 Cover & Control'!$C$19="Upside",F50,F51)) -> 78 | G52: =IF('01 Cover & Control'!$C$19="Base",G49,IF('01 Cover & Control'!$C$19="Upside",G50,G51)) -> 78 | H52: =IF('01 Cover & Control'!$C$19="Base",H49,IF('01 Cover & Control'!$C$19="Upside",H50,H51)) -> 78 | I52: =SUM(E52:H52) -> 312 | J52: =IF('01 Cover & Control'!$C$19="Base",J49,IF('01 Cover & Control'!$C$19="Upside",J50,J51)) -> 82 | K52: =IF('01 Cover & Control'!$C$19="Base",K49,IF('01 Cover & Control'!$C$19="Upside",K50,K51)) -> 82 | L52: =IF('01 Cover & Control'!$C$19="Base",L49,IF('01 Cover & Control'!$C$19="Upside",L50,L51)) -> 82 | M52: =IF('01 Cover & Control'!$C$19="Base",M49,IF('01 Cover & Control'!$C$19="Upside",M50,M51)) -> 82 | N52: =SUM(J52:M52) -> 328 | O52: =IF('01 Cover & Control'!$C$19="Base",O49,IF('01 Cover & Control'!$C$19="Upside",O50,O51)) -> 92 | P52: =IF('01 Cover & Control'!$C$19="Base",P49,IF('01 Cover & Control'!$C$19="Upside",P50,P51)) -> 92 | Q52: =IF('01 Cover & Control'!$C$19="Base",Q49,IF('01 Cover & Control'!$C$19="Upside",Q50,Q51)) -> 92 | R52: =IF('01 Cover & Control'!$C$19="Base",R49,IF('01 Cover & Control'!$C$19="Upside",R50,R51)) -> 92 | S52: =SUM(O52:R52) -> 368 | T52: =IF('01 Cover & Control'!$C$19="Base",T49,IF('01 Cover & Control'!$C$19="Upside",T50,T51)) -> 105 | U52: =IF('01 Cover & Control'!$C$19="Base",U49,IF('01 Cover & Control'!$C$19="Upside",U50,U51)) -> 105 | V52: =IF('01 Cover & Control'!$C$19="Base",V49,IF('01 Cover & Control'!$C$19="Upside",V50,V51)) -> 105 | W52: =IF('01 Cover & Control'!$C$19="Base",W49,IF('01 Cover & Control'!$C$19="Upside",W50,W51)) -> 105 | X52: =SUM(T52:W52) -> 420 | Y52: =IF('01 Cover & Control'!$C$19="Base",Y49,IF('01 Cover & Control'!$C$19="Upside",Y50,Y51)) -> 112 | Z52: =IF('01 Cover & Control'!$C$19="Base",Z49,IF('01 Cover & Control'!$C$19="Upside",Z50,Z51)) -> 112 | AA52: =IF('01 Cover & Control'!$C$19="Base",AA49,IF('01 Cover & Control'!$C$19="Upside",AA50,AA51)) -> 112 | AB52: =IF('01 Cover & Control'!$C$19="Base",AB49,IF('01 Cover & Control'!$C$19="Upside",AB50,AB51)) -> 112 | AC52: =SUM(Y52:AB52) -> 448 | AD52: =IF('01 Cover & Control'!$C$19="Base",AD49,IF('01 Cover & Control'!$C$19="Upside",AD50,AD51)) -> 118 | AE52: =IF('01 Cover & Control'!$C$19="Base",AE49,IF('01 Cover & Control'!$C$19="Upside",AE50,AE51)) -> 118 | AF52: =IF('01 Cover & Control'!$C$19="Base",AF49,IF('01 Cover & Control'!$C$19="Upside",AF50,AF51)) -> 118 | AG52: =IF('01 Cover & Control'!$C$19="Base",AG49,IF('01 Cover & Control'!$C$19="Upside",AG50,AG51)) -> 118 | AH52: =SUM(AD52:AG52) -> 472 | AI52: =IF('01 Cover & Control'!$C$19="Base",AI49,IF('01 Cover & Control'!$C$19="Upside",AI50,AI51)) -> 122 | AJ52: =IF('01 Cover & Control'!$C$19="Base",AJ49,IF('01 Cover & Control'!$C$19="Upside",AJ50,AJ51)) -> 122 | AK52: =IF('01 Cover & Control'!$C$19="Base",AK49,IF('01 Cover & Control'!$C$19="Upside",AK50,AK51)) -> 122 | AL52: =IF('01 Cover & Control'!$C$19="Base",AL49,IF('01 Cover & Control'!$C$19="Upside",AL50,AL51)) -> 122 | AM52: =SUM(AI52:AL52) -> 488 | AN52: =IF('01 Cover & Control'!$C$19="Base",AN49,IF('01 Cover & Control'!$C$19="Upside",AN50,AN51)) -> 126 | AO52: =IF('01 Cover & Control'!$C$19="Base",AO49,IF('01 Cover & Control'!$C$19="Upside",AO50,AO51)) -> 126 | AP52: =IF('01 Cover & Control'!$C$19="Base",AP49,IF('01 Cover & Control'!$C$19="Upside",AP50,AP51)) -> 126 | AQ52: =IF('01 Cover & Control'!$C$19="Base",AQ49,IF('01 Cover & Control'!$C$19="Upside",AQ50,AQ51)) -> 126 | AR52: =SUM(AN52:AQ52) -> 504
B54: IS Market Velocity Index (2023 = 100) — Base | C54: Index | D54: MSCI RCA; internal calibration. Reflects deal count velocity vs base year. | E54: 100 | F54: 100 | G54: 100 | H54: 100 | I54: =SUM(E54:H54) -> 400 | J54: 100 | K54: 100 | L54: 100 | M54: 100 | N54: =SUM(J54:M54) -> 400 | O54: 100 | P54: 100 | Q54: 100 | R54: 100 | S54: =SUM(O54:R54) -> 400 | T54: 100 | U54: 100 | V54: 100 | W54: 100 | X54: =SUM(T54:W54) -> 400 | Y54: 100 | Z54: 100 | AA54: 100 | AB54: 100 | AC54: =SUM(Y54:AB54) -> 400 | AD54: 100 | AE54: 100 | AF54: 100 | AG54: 100 | AH54: =SUM(AD54:AG54) -> 400 | AI54: 100 | AJ54: 100 | AK54: 100 | AL54: 100 | AM54: =SUM(AI54:AL54) -> 400 | AN54: 100 | AO54: 100 | AP54: 100 | AQ54: 100 | AR54: =SUM(AN54:AQ54) -> 400
...

Sheet 03 Operational Assumptions
A1: 03 | OPERATIONAL ASSUMPTIONS — FIRM-CONTROLLED DRIVERS
A2: Scenario-sensitive rows: Base / Upside / Downside / Active. Active rows link to Tab 01 C19. Static tables use different column layout (noted inline). | E2: ='01 Cover & Control'!C19 -> Base
B3: Assumption / Row | C3: Units | D3: Source / Notes | E3: 2023A Q1 | F3: 2023A Q2 | G3: 2023A Q3 | H3: 2023A Q4 | I3: 2023A Annual | J3: 2024A Q1 | K3: 2024A Q2 | L3: 2024A Q3 | M3: 2024A Q4 | N3: 2024A Annual | O3: 2025A Q1 | P3: 2025A Q2 | Q3: 2025A Q3 | R3: 2025A Q4 | S3: 2025A Annual | T3: 2026E Q1 | U3: 2026E Q2 | V3: 2026E Q3 | W3: 2026E Q4 | X3: 2026E Annual | Y3: 2027E Q1 | Z3: 2027E Q2 | AA3: 2027E Q3 | AB3: 2027E Q4 | AC3: 2027E Annual | AD3: 2028E Q1 | AE3: 2028E Q2 | AF3: 2028E Q3 | AG3: 2028E Q4 | AH3: 2028E Annual | AI3: 2029E Q1 | AJ3: 2029E Q2 | AK3: 2029E Q3 | AL3: 2029E Q4 | AM3: 2029E Annual | AN3: 2030E Q1 | AO3: 2030E Q2 | AP3: 2030E Q3 | AQ3: 2030E Q4 | AR3: 2030E Annual
A5: SECTION A — HEADCOUNT PLAN | EPE = Beginning HC + (Hires × Ramp Factor) − Attrition
A7: Beginning Headcount: input once per year (Q1 of each year). Hires & Attrition Rate: scenario-keyed quarterly inputs. Attrition rate applied to Beginning HC in the Producer Engine: Attrition = Rate × Beginning HC. Historical period: enter actuals. Forecast period: scenario-keyed inputs.
A9: LEASING — HEADCOUNT
B11: Beginning HC — Rainmaker | C11: # | D11: Input: actuals for hist period; forecast = prior yr ending HC. Used directly in EPE formula. | E11: 8 | I11: =SUM(E11:H11) -> 8 | N11: =SUM(J11:M11) -> 0 | S11: =SUM(O11:R11) -> 0 | X11: =SUM(T11:W11) -> 0 | AC11: =SUM(Y11:AB11) -> 0 | AH11: =SUM(AD11:AG11) -> 0 | AM11: =SUM(AI11:AL11) -> 0 | AR11: =SUM(AN11:AQ11) -> 0
B12: Gross Hires / Qtr — Rainmaker — Base | C12: #/qtr | D12: Scenario-keyed. Upside = faster hiring. Downside = slower/failed hiring. | E12: 0.5 | F12: 0.5 | G12: 0.5 | H12: 0.5 | I12: =SUM(E12:H12) -> 2 | J12: 0.5 | K12: 0.5 | L12: 0.5 | M12: 0.5 | N12: =SUM(J12:M12) -> 2 | O12: 0.5 | P12: 0.5 | Q12: 0.5 | R12: 0.5 | S12: =SUM(O12:R12) -> 2 | T12: 0.5 | U12: 0.5 | V12: 0.5 | W12: 0.5 | X12: =SUM(T12:W12) -> 2 | Y12: 0.5 | Z12: 0.5 | AA12: 0.5 | AB12: 0.5 | AC12: =SUM(Y12:AB12) -> 2 | AD12: 0.5 | AE12: 0.5 | AF12: 0.5 | AG12: 0.5 | AH12: =SUM(AD12:AG12) -> 2 | AI12: 0.5 | AJ12: 0.5 | AK12: 0.5 | AL12: 0.5 | AM12: =SUM(AI12:AL12) -> 2 | AN12: 0.5 | AO12: 0.5 | AP12: 0.5 | AQ12: 0.5 | AR12: =SUM(AN12:AQ12) -> 2
B13: Gross Hires / Qtr — Rainmaker — Upside | E13: 0.55 | F13: 0.55 | G13: 0.55 | H13: 0.55 | I13: =SUM(E13:H13) -> 2.2 | J13: 0.55 | K13: 0.55 | L13: 0.55 | M13: 0.55 | N13: =SUM(J13:M13) -> 2.2 | O13: 0.55 | P13: 0.55 | Q13: 0.55 | R13: 0.55 | S13: =SUM(O13:R13) -> 2.2 | T13: 0.55 | U13: 0.55 | V13: 0.55 | W13: 0.55 | X13: =SUM(T13:W13) -> 2.2 | Y13: 0.55 | Z13: 0.55 | AA13: 0.55 | AB13: 0.55 | AC13: =SUM(Y13:AB13) -> 2.2 | AD13: 0.55 | AE13: 0.55 | AF13: 0.55 | AG13: 0.55 | AH13: =SUM(AD13:AG13) -> 2.2 | AI13: 0.55 | AJ13: 0.55 | AK13: 0.55 | AL13: 0.55 | AM13: =SUM(AI13:AL13) -> 2.2 | AN13: 0.55 | AO13: 0.55 | AP13: 0.55 | AQ13: 0.55 | AR13: =SUM(AN13:AQ13) -> 2.2
B14: Gross Hires / Qtr — Rainmaker — Downside | E14: 0.42 | F14: 0.42 | G14: 0.42 | H14: 0.42 | I14: =SUM(E14:H14) -> 1.68 | J14: 0.42 | K14: 0.42 | L14: 0.42 | M14: 0.42 | N14: =SUM(J14:M14) -> 1.68 | O14: 0.42 | P14: 0.42 | Q14: 0.42 | R14: 0.42 | S14: =SUM(O14:R14) -> 1.68 | T14: 0.42 | U14: 0.42 | V14: 0.42 | W14: 0.42 | X14: =SUM(T14:W14) -> 1.68 | Y14: 0.42 | Z14: 0.42 | AA14: 0.42 | AB14: 0.42 | AC14: =SUM(Y14:AB14) -> 1.68 | AD14: 0.42 | AE14: 0.42 | AF14: 0.42 | AG14: 0.42 | AH14: =SUM(AD14:AG14) -> 1.68 | AI14: 0.42 | AJ14: 0.42 | AK14: 0.42 | AL14: 0.42 | AM14: =SUM(AI14:AL14) -> 1.68 | AN14: 0.42 | AO14: 0.42 | AP14: 0.42 | AQ14: 0.42 | AR14: =SUM(AN14:AQ14) -> 1.68
