Workbook

Sheet Cover
B2: PROLOGIS, INC. (NYSE: PLD)
B3: Equity Valuation - DCF, NAV & Trading Comparables
B4: Independent analysis - public data only - not investment advice
B7: Prepared by: | C7: Muhammed Sheikh
B8: Date: | C8: 46175
B9: Model version: | C9: v0.1 - skeleton
B10: Valuation basis: | C10: Prologis share unless labeled O&M
B11: Reporting currency: | C11: USD ($ in thousands unless noted)
B13: MODEL STATUS
B14: Master audit flag: | C14: =IF(COUNTIF(Audit!E:E,"ERROR")=0,"MODEL OK","ERRORS PRESENT — see Audit tab") -> MODEL OK
B16: VERSION LOG
B17: Date | C17: Change / session notes

Sheet ReadMe
A1: READ ME - CONVENTIONS & SOURCE INDEX
A3: COLOR CONVENTIONS
A4: Blue font | B4: Hardcoded input typed from a source document. Lives ONLY on Data_Collection.
A5: Black font | B5: Formula calculated within the same tab.
A6: Green font | B6: Link pulling from another tab in this workbook.
A7: Red font | B7: Flag / error / external link (avoid external links entirely).
A8: Peach fill | B8: Pre-filled by assistant from Q1'26 release — VERIFY against filing & replace placeholder periods.
A10: CHECK ROWS | B10: Live IF formulas returning OK/ERROR; ERROR conditionally formatted red. Master flag on Cover.
A11: UNITS | B11: $ in millions unless a row says otherwise. Basis = Prologis share unless labeled O&M.
A12: "n/d" | B12: Not disclosed in filings. Never replace with an estimate.
A14: SOURCE DOCUMENT INDEX (fill file names + dates as you download)
A15: [10-K] | B15: PLD Form 10-K FY2025 — SEC EDGAR CIK 1045609
A16: [10-K24/23] | B16: PLD Form 10-K FY2024 / FY2023
A17: [10-Q] | B17: PLD Form 10-Q Q1 2026
A18: [SUPP] | B18: PLD Supplemental Information Q1 2026 — ir.prologis.com
A19: [ER] | B19: PLD Q1 2026 Earnings Release — 8-K Ex.99.2, filed 2026-04-16
A21: BUILD ORDER | B21: Data_Collection → Historicals → FFO_Recon (must tie) → Drivers/Development/Strategic_Capital/Capital_Deployment/Debt/Share_Count → Audit. Then Assumptions → Model → Scenarios → DCF → NAV → Comps → Summary.

Sheet Data_Collection
A1: PROLOGIS - DATA COLLECTION
A2: ($ in thousands unless noted) | B2: FY2023 | C2: FY2024 | D2: FY2025 | E2: Q1 2026 | F2: Source | G2: Section | H2: Page
A3: GROUP 1: INCOME STATEMENT
A4: Rental revenue | B4: 6818542 | C4: 7514705 | D4: 8158904 | E4: 2125084 | F4: Source: PLD Q4 2025 10-K p.55 (FY23/FY24/FY25); Q1 2026 10Q p.55 (Q1 26).
A5: Strategic capital revenue | B5: 1200232 | C5: 671907 | D5: 592353 | E5: 160812
A6: Development management & other revenue | B6: 4695 | C6: 14998 | D6: 38870 | E6: 11827
A7: Rental expenses | B7: 1624793 | C7: 1765385 | D7: 1964137 | E7: 520283
A8: Strategic capital expenses | B8: 385542 | C8: 291856 | D8: 270517 | E8: 81889
A9: General & administrative | B9: 390406 | C9: 418765 | D9: 469114 | E9: 126890
A10: Depreciation & amortization | B10: 2484891 | C10: 2580519 | D10: 2626028 | E10: 731506
A11: Other expenses | B11: 53354 | C11: 47044 | D11: 46029 | E11: 10123
A12: Gains on dispositions of real estate, net | B12: =462270+161039 -> 623309 | C12: =904136+413743 -> 1317879 | D12: =257731+685831 -> 943562 | E12: 384023
A13: Earnings from unconsolidated entities, net | B13: 307227 | C13: 353623 | D13: 402531 | E13: 93296
A14: Interest expense | B14: -641332 | C14: -863932 | D14: -1002344 | E14: -254286
A15: Interest and other income, net | B15: -243609 | C15: -301042 | D15: -588548 | E15: -118269
A16: Foreign currency & derivative gains (losses), net | B16: 87221 | C16: 208731 | D16: 14763 | E16: 44611
A17: Gains (losses) on early extinguishment of debt, net | B17: 3275 | C17: 536 | D17: -3498 | E17: -1890
A18: Income tax expense | B18: 211038 | C18: 166943 | D18: 204017 | E18: 47971
A19: Net earnings attributable to NCI | B19: 193931 | C19: 216300 | D19: 237068 | E19: 39978
A20: Preferred dividends | B20: 5841 | C20: 5881 | D20: 5882 | E20: 1500
A21: Net earnings attributable to common | B21: 3053373 | C21: 3725754 | D21: 3322349 | E21: 1003337
A22: Weighted Avg Shares – Basic | B22: 924351 | C22: 926172 | D22: 928473 | E22: 952981
A23: Weighted Avg Shares – Diluted | B23: 951791 | C23: 953590 | D23: 956832 | E23: 957561
A25: GROUP 2: BALANCE SHEET
A26: Investments in real estate properties (gross) | B26: 88666575 | C26: 91246176 | D26: 95129356 | E26: 95241445 | F26: Source: PLD Q4 2025 10-K p.55 (FY23/FY24/FY25); Q1 2026 10Q p.55 (Q1 26).
A27: Accumulated depreciation | B27: 10931485 | C27: 12758159 | D27: 14729149 | E27: 15298353
A28: Investments in/advances to unconsolidated entities | B28: 9543970 | C28: 10079448 | D28: 11093936 | E28: 11241723
A29: Assets held for sale or contribution | B29: 461657 | C29: 248511 | D29: 203344 | E29: 499799
A30: Cash and cash equivalents | B30: 530388 | C30: 1318591 | D30: 1145647 | E30: 861144
A31: Other assets | B31: 4749735 | C31: 5194342 | D31: 5881122 | E31: 5587693
A32: Total assets (reported) | B32: 93020840 | C32: 95328099 | D32: 98724256 | E32: 98133451
A33: Debt (carrying value per BS) | B33: 29000501 | C33: 30879263 | D33: 35037073 | E33: 34669592
A34: Accounts payable & accrued expenses | B34: 1766018 | C34: 1769327 | D34: 1963645 | E34: 1681047
A35: Other liabilities | B35: 4430601 | C35: 4063549 | D35: 3969530 | E35: 3834320
A36: Total liabilities (reported) | B36: 35197120 | C36: 36712139 | D36: 40970248 | E36: 40184959
A37: Preferred stock | B37: 63948 | C37: 63948 | D37: 63948 | E37: 63948
A38: Total stockholders' equity (reported) | B38: 53181724 | C38: 53951138 | D38: 53193178 | E38: 53503401
... A40: Total equity (reported) | B40: 57823720 | C40: 58616770 | D40: 57754008 | E40: 57948492
A42: GROUP 3: CASH FLOW
A43: Consolidated net earnings | B43: 3253145 | C43: 3947935 | D43: 3565299 | E43: 1044815 | F43: Source: PLD Q4 2025 10-K p.55 (FY23/FY24/FY25); Q1 2026 10Q p.55 (Q1 26).
...

Sheet Historicals
A1: HISTORICALS - IS / BS / CF
A2: All cells link (green) to Data_Collection or calculate (black). Zero hardcodes.
A4: ($ in millions unless noted) | B4: FY2023 | C4: FY2024 | D4: FY2025 | E4: Q1 2026
A5: INCOME STATEMENT
A6: Rental revenue | B6: =Data_Collection!B4 -> 6818542 | C6: =Data_Collection!C4 -> 7514705 | D6: =Data_Collection!D4 -> 8158904 | E6: =Data_Collection!E4 -> 2125084
A7: Strategic capital revenue | B7: =Data_Collection!B5 -> 1200232 | C7: =Data_Collection!C5 -> 671907 | D7: =Data_Collection!D5 -> 592353 | E7: =Data_Collection!E5 -> 160812
A8: Development management & other revenue | B8: =Data_Collection!B6 -> 4695 | C8: =Data_Collection!C6 -> 14998 | D8: =Data_Collection!D6 -> 38870 | E8: =Data_Collection!E6 -> 11827
A9: Total revenues | B9: =SUM(B6:B8) -> 8023469 | C9: =SUM(C6:C8) -> 8201610 | D9: =SUM(D6:D8) -> 8790127 | E9: =SUM(E6:E8) -> 2297723
A10: Rental expenses | B10: =-Data_Collection!B7 -> -1624793 | C10: =-Data_Collection!C7 -> -1765385 | D10: =-Data_Collection!D7 -> -1964137 | E10: =-Data_Collection!E7 -> -520283
A11: Strategic capital expenses | B11: =-Data_Collection!B8 -> -385542 | C11: =-Data_Collection!C8 -> -291856 | D11: =-Data_Collection!D8 -> -270517 | E11: =-Data_Collection!E8 -> -81889
A12: General & administrative | B12: =-Data_Collection!B9 -> -390406 | C12: =-Data_Collection!C9 -> -418765 | D12: =-Data_Collection!D9 -> -469114 | E12: =-Data_Collection!E9 -> -126890
A13: Depreciation & amortization | B13: =-Data_Collection!B10 -> -2484891 | C13: =-Data_Collection!C10 -> -2580519 | D13: =-Data_Collection!D10 -> -2626028 | E13: =-Data_Collection!E10 -> -731506
A14: Other expenses | B14: =-Data_Collection!B11 -> -53354 | C14: =-Data_Collection!C11 -> -47044 | D14: =-Data_Collection!D11 -> -46029 | E14: =-Data_Collection!E11 -> -10123
A15: Total expenses | B15: =SUM(B10:B14) -> -4938986 | C15: =SUM(C10:C14) -> -5103569 | D15: =SUM(D10:D14) -> -5375825 | E15: =SUM(E10:E14) -> -1470691
A16: Operating income before gains | B16: =B9+B15 -> 3084483 | C16: =C9+C15 -> 3098041 | D16: =D9+D15 -> 3414302 | E16: =E9+E15 -> 827032
A17: Gains on dispositions of real estate, net | B17: =Data_Collection!B12 -> 623309 | C17: =Data_Collection!C12 -> 1317879 | D17: =Data_Collection!D12 -> 943562 | E17: =Data_Collection!E12 -> 384023
A18: Operating income | B18: =B16+B17 -> 3707792 | C18: =C16+C17 -> 4415920 | D18: =D16+D17 -> 4357864 | E18: =E16+E17 -> 1211055
A19: Earnings from unconsolidated entities, net | B19: =Data_Collection!B13 -> 307227 | C19: =Data_Collection!C13 -> 353623 | D19: =Data_Collection!D13 -> 402531 | E19: =Data_Collection!E13 -> 93296
A20: Interest expense | B20: =Data_Collection!B14 -> -641332 | C20: =Data_Collection!C14 -> -863932 | D20: =Data_Collection!D14 -> -1002344 | E20: =Data_Collection!E14 -> -254286
A21: Interest and other income, net | B21: =Data_Collection!B15 -> -243609 | C21: =Data_Collection!C15 -> -301042 | D21: =Data_Collection!D15 -> -588548 | E21: =Data_Collection!E15 -> -118269
A22: Foreign currency & derivative gains (losses), net | B22: =Data_Collection!B16 -> 87221 | C22: =Data_Collection!C16 -> 208731 | D22: =Data_Collection!D16 -> 14763 | E22: =Data_Collection!E16 -> 44611
A23: Gains (losses) on early extinguishment of debt, net | B23: =Data_Collection!B17 -> 3275 | C23: =Data_Collection!C17 -> 536 | D23: =Data_Collection!D17 -> -3498 | E23: =Data_Collection!E17 -> -1890
A24: Pre-tax earnings | B24: =B18+SUM(B19:B20)+SUM(B22:B23) -> 3464183 | C24: =C18+SUM(C19:C20)+SUM(C22:C23) -> 4114878 | D24: =D18+SUM(D19:D20)+SUM(D22:D23) -> 3769316 | E24: =E18+SUM(E19:E20)+SUM(E22:E23) -> 1092786
A25: Income tax expense | B25: =-Data_Collection!B18 -> -211038 | C25: =-Data_Collection!C18 -> -166943 | D25: =-Data_Collection!D18 -> -204017 | E25: =-Data_Collection!E18 -> -47971
A26: Consolidated net earnings | B26: =B24+B25 -> 3253145 | C26: =C24+C25 -> 3947935 | D26: =D24+D25 -> 3565299 | E26: =E24+E25 -> 1044815
A27: Less: net earnings attributable to NCI | B27: =-Data_Collection!B19 -> -193931 | C27: =-Data_Collection!C19 -> -216300 | D27: =-Data_Collection!D19 -> -237068 | E27: =-Data_Collection!E19 -> -39978
A28: Less: preferred dividends | B28: =-Data_Collection!B20 -> -5841 | C28: =-Data_Collection!C20 -> -5881 | D28: =-Data_Collection!D20 -> -5882 | E28: =-Data_Collection!E20 -> -1500
A29: Net earnings attributable to common | B29: =B26+B27+B28 -> 3053373 | C29: =C26+C27+C28 -> 3725754 | D29: =D26+D27+D28 -> 3322349 | E29: =E26+E27+E28 -> 1003337
A31: MEMO - Property NOI | B31: =B6+B10 -> 5193749 | C31: =C6+C10 -> 5749320 | D31: =D6+D10 -> 6194767 | E31: =E6+E10 -> 1604801
A32: MEMO - NOI margin % | B32: =IF(B6=0,0,B31/B6) -> 0.76170961 | C32: =IF(C6=0,0,C31/C6) -> 0.76507594 | D32: =IF(D6=0,0,D31/D6) -> 0.7592646 | E32: =IF(E6=0,0,E31/E6) -> 0.75517062
A34: BALANCE SHEET
A35: Investments in real estate (gross) | B35: =Data_Collection!B26 -> 88666575 | C35: =Data_Collection!C26 -> 91246176 | D35: =Data_Collection!D26 -> 95129356 | E35: =Data_Collection!E26 -> 95241445
A36: Less: accumulated depreciation | B36: =-Data_Collection!B27 -> -10931485 | C36: =-Data_Collection!C27 -> -12758159 | D36: =-Data_Collection!D27 -> -14729149 | E36: =-Data_Collection!E27 -> -15298353
A37: Net investments in real estate properties | B37: =B35+B36 -> 77735090 | C37: =C35+C36 -> 78488017 | D37: =D35+D36 -> 80400207 | E37: =E35+E36 -> 79943092
A38: Investments in/advances to unconsolidated | B38: =Data_Collection!B28 -> 9543970 | C38: =Data_Collection!C28 -> 10079448 | D38: =Data_Collection!D28 -> 11093936 | E38: =Data_Collection!E28 -> 11241723
A39: Assets held for sale or contribution | B39: =Data_Collection!B29 -> 461657 | C39: =Data_Collection!C29 -> 248511 | D39: =Data_Collection!D29 -> 203344 | E39: =Data_Collection!E29 -> 499799
A40: Net investments in real estate | B40: =B37+B38+B39 -> 87740717 | C40: =C37+C38+C39 -> 88815976 | D40: =D37+D38+D39 -> 91697487 | E40: =E37+E38+E39 -> 91684614
A41: Cash and cash equivalents | B41: =Data_Collection!B30 -> 530388 | C41: =Data_Collection!C30 -> 1318591 | D41: =Data_Collection!D30 -> 1145647 | E41: =Data_Collection!E30 -> 861144
A42: Other assets | B42: =Data_Collection!B31 -> 4749735 | C42: =Data_Collection!C31 -> 5194342 | D42: =Data_Collection!D31 -> 5881122 | E42: =Data_Collection!E31 -> 5587693
A43: TOTAL ASSETS | B43: =B40+B41+B42 -> 93020840 | C43: =C40+C41+C42 -> 95328909 | D43: =D40+D41+D42 -> 98724256 | E43: =E40+E41+E42 -> 98133451
...

Sheet FFO_Recon
A1: FFO / CORE FFO / AFFO RECONCILIATION
A3: ($ in thousands; per-share in $) | B3: FY2023 | C3: FY2024 | D3: FY2025 | E3: Q1 2026
A4: NAREIT FFO
A5: Net earnings attributable to common | B5: =Data_Collection!B168 -> 3053373 | C5: =Data_Collection!C168 -> 3725754 | D5: =Data_Collection!D168 -> 3322349 | E5: =Data_Collection!E168 -> 980476
A6: + Real estate related depreciation & amortization | B6: =Data_Collection!B169 -> 2433610 | C6: =Data_Collection!C169 -> 2504001 | D6: =Data_Collection!D169 -> 2538805 | E6: =Data_Collection!E169 -> 705550
A7: − Gains on other dispositions of RE, net of tax | B7: =Data_Collection!B170 -> -157940 | C7: =Data_Collection!C170 -> -899270 | D7: =Data_Collection!D170 -> -684854 | E7: =Data_Collection!E170 -> -91040
A8: ± Reconciling items attributable to NCI | B8: =Data_Collection!B171 -> -38246 | C8: =Data_Collection!C171 -> -31334 | D8: =Data_Collection!D171 -> -47819 | E8: =Data_Collection!E171 -> -10737
A9: + Our prop. share of adjustments - unconsolidated | B9: =Data_Collection!B172 -> 455355 | C9: =Data_Collection!C172 -> 495448 | D9: =Data_Collection!D172 -> 551044 | E9: =Data_Collection!E172 -> 151155
A10: NAREIT FFO | B10: =SUM(B5:B9) -> 5746152 | C10: =SUM(C5:C9) -> 5794599 | D10: =SUM(D5:D9) -> 5679525 | E10: =SUM(E5:E9) -> 1735404
A11: CHECK: vs reported NAREIT FFO | B11: =IF(Data_Collection!B63="","n/a",IF(ABS(B10-Data_Collection!B63)<1,"OK","ERROR")) -> OK | C11: =IF(Data_Collection!C63="","n/a",IF(ABS(C10-Data_Collection!C63)<1,"OK","ERROR")) -> OK | D11: =IF(Data_Collection!D63="","n/a",IF(ABS(D10-Data_Collection!D63)<1,"OK","ERROR")) -> OK | E11: =IF(Data_Collection!E63="","n/a",IF(ABS(E10-Data_Collection!E63)<1,"OK","ERROR")) -> OK
A13: FFO, as modified by Prologis
A14: NAREIT FFO (carryforward) | B14: =B10 -> 5746152 | C14: =C10 -> 5794599 | D14: =D10 -> 5679525 | E14: =E10 -> 1735404
A15: ± Unrealized FX, derivative & other (gains) losses, net | B15: =Data_Collection!B173 -> 17619 | C15: =Data_Collection!C173 -> -68095 | D15: =Data_Collection!D173 -> 125247 | E15: =Data_Collection!E173 -> -14269
A16: ± Deferred income tax expense (benefit) | B16: =Data_Collection!B174 -> 6705 | C16: =Data_Collection!C174 -> 21161 | D16: =Data_Collection!D174 -> 4309 | E16: =Data_Collection!E174 -> 190
A17: ± Adjustments related to NCI | B17: =Data_Collection!B175 -> 403 | C17: =Data_Collection!C175 -> 0 | D17: =Data_Collection!D175 -> -728 | E17: =Data_Collection!E175 -> 712
A18: ± Our prop. share of adjustments - unconsolidated | B18: =Data_Collection!B176 -> -11224 | C18: =Data_Collection!C176 -> -7038 | D18: =Data_Collection!D176 -> -29094 | E18: =Data_Collection!E176 -> -725
A19: FFO, as modified by Prologis | B19: =SUM(B14:B18) -> 5759655 | C19: =SUM(C14:C18) -> 5740627 | D19: =SUM(D14:D18) -> 5779259 | E19: =SUM(E14:E18) -> 1721312
A20: CHECK: vs reported FFO as modified | B20: =IF(Data_Collection!B191="","n/a",IF(ABS(B19-Data_Collection!B191)<1,"OK","ERROR")) -> OK | C20: =IF(Data_Collection!C191="","n/a",IF(ABS(C19-Data_Collection!C191)<1,"OK","ERROR")) -> OK | D20: =IF(Data_Collection!D191="","n/a",IF(ABS(D19-Data_Collection!D191)<1,"OK","ERROR")) -> OK | E20: =IF(Data_Collection!E191="","n/a",IF(ABS(E19-Data_Collection!E191)<1,"OK","ERROR")) -> OK
A21: Core FFO
A22: FFO, as modified by Prologis (carryforward) | B22: =B19 -> 5759655 | C22: =C19 -> 5740627 | D22: =D19 -> 5779259 | E22: =E19 -> 1721312
A23: − Gains on dispositions of dev properties & land, net | B23: =Data_Collection!B177 -> -462270 | C23: =Data_Collection!C177 -> -413743 | D23: =Data_Collection!D177 -> -257731 | E23: =Data_Collection!E177 -> -292983
A24: ± Current income tax on dispositions | B24: =Data_Collection!B178 -> 36125 | C24: =Data_Collection!C178 -> 24876 | D24: =Data_Collection!D178 -> 25738 | E24: =Data_Collection!E178 -> 1302
A25: ± (Gains) losses on early extinguishment of debt | B25: =Data_Collection!B179 -> -3275 | C25: =Data_Collection!C179 -> -536 | D25: =Data_Collection!D179 -> 3498 | E25: =Data_Collection!E179 -> 1890
A26: ± Adjustments related to NCI | B26: =Data_Collection!B180 -> 9359 | C26: =Data_Collection!C180 -> 6244 | D26: =Data_Collection!D180 -> 14944 | E26: =Data_Collection!E180 -> 271
A27: ± Our prop. share of adjustments - unconsolidated | B27: =Data_Collection!B181 -> -5344 | C27: =Data_Collection!C181 -> -52529 | D27: =Data_Collection!D181 -> -4408 | E27: =Data_Collection!E181 -> 8701
A28: Core FFO | B28: =SUM(B22:B27) -> 5334250 | C28: =SUM(C22:C27) -> 5304939 | D28: =SUM(D22:D27) -> 5561300 | E28: =SUM(E22:E27) -> 1440493
A29: CHECK: vs reported Core FFO ($) | B29: =IF(Data_Collection!B65="","n/a",IF(ABS(B28-Data_Collection!B65)<1,"OK","ERROR")) -> OK | C29: =IF(Data_Collection!C65="","n/a",IF(ABS(C28-Data_Collection!C65)<1,"OK","ERROR")) -> OK | D29: =IF(Data_Collection!D65="","n/a",IF(ABS(D28-Data_Collection!D65)<1,"OK","ERROR")) -> OK | E29: =IF(Data_Collection!E65="","n/a",IF(ABS(E28-Data_Collection!E65)<1,"OK","ERROR")) -> OK
A30: Core FFO per share | B30: =B28/1000/Share_Count!B8 -> 5.6020269 | C30: =C28/1000/Share_Count!C8 -> 5.5601499 | D30: =D28/1000/Share_Count!D8 -> 5.8099666 | E30: =E28/1000/Share_Count!E8 -> 1.5000448
A31: CHECK: vs reported Core FFO/share (±$0.005) | B31: =IF(Data_Collection!B66="","n/a",IF(ABS(B30-Data_Collection!B66)<0.005,"OK","ERROR")) -> OK | C31: =IF(Data_Collection!C66="","n/a",IF(ABS(C30-Data_Collection!C66)<0.005,"OK","ERROR")) -> OK | D31: =IF(Data_Collection!D66="","n/a",IF(ABS(D30-Data_Collection!D66)<0.005,"OK","ERROR")) -> OK | E31: =IF(Data_Collection!E66="","n/a",IF(ABS(E30-Data_Collection!E66)<0.005,"OK","ERROR")) -> OK
A32: MEMO: Net promote income (expense) | B32: =Data_Collection!B130 -> 478944 | C32: =Data_Collection!C130 -> 31714 | D32: =Data_Collection!D130 -> -48960 | E32: =Data_Collection!E130 -> -50448
A34: AFFO
A35: Core FFO (carryforward) | B35: =B28 -> 5334250 | C35: =C28 -> 5304939 | D35: =D28 -> 5561300 | E35: =E28 -> 1440493
A36: + Gains on disp dev properties & land (add back) | B36: =Data_Collection!B182 -> 462270 | C36: =Data_Collection!C182 -> 413743 | D36: =Data_Collection!D182 -> 257731 | E36: =Data_Collection!E182 -> 292983
A37: − Current income tax on dispositions | B37: =Data_Collection!B183 -> -36125 | C37: =Data_Collection!C183 -> -24876 | D37: =Data_Collection!D183 -> -25738 | E37: =Data_Collection!E183 -> -1302
A38: − Straight-line rents & lease intangible amort. | B38: =Data_Collection!B184 -> -625356 | C38: =Data_Collection!C184 -> -644606 | D38: =Data_Collection!D184 -> -691090 | E38: =Data_Collection!E184 -> -165749
A39: − Property improvements | B39: =Data_Collection!B185 -> -303042 | C39: =Data_Collection!C185 -> -386481 | D39: =Data_Collection!D185 -> -327355 | E39: =Data_Collection!E185 -> -26065
A40: − Turnover costs (TI + LC) | B40: =Data_Collection!B186 -> -388814 | C40: =Data_Collection!C186 -> -499927 | D40: =Data_Collection!D186 -> -562197 | E40: =Data_Collection!E186 -> -123816
A41: + Amort of debt disc/financing/mgmt contracts | B41: =Data_Collection!B187 -> 76294 | C41: =Data_Collection!C187 -> 80028 | D41: =Data_Collection!D187 -> 90668 | E41: =Data_Collection!E187 -> 21400
A42: + Stock compensation amortization | B42: =Data_Collection!B188 -> 267648 | C42: =Data_Collection!C188 -> 231747 | D42: =Data_Collection!D188 -> 185466 | E42: =Data_Collection!E188 -> 60632
A43: ± Adjustments related to NCI | B43: =Data_Collection!B189 -> 48049 | C43: =Data_Collection!C189 -> 53432 | D43: =Data_Collection!D189 -> 66005 | E43: =Data_Collection!E189 -> 19628
...

Sheet Drivers
A1: OPERATING DRIVERS
A2: Green = link, blue = input, black = calc.
A4: ($ in millions unless noted) | B4: FY2023 | C4: FY2024 | D4: FY2025 | E4: Q1 2026
A5: OCCUPANCY
A6: Average occupancy % - PLD share | B6: =Data_Collection!B88 -> 0.977 | C6: =Data_Collection!C88 -> 0.958 | D6: =Data_Collection!D88 -> 0.956 | E6: =Data_Collection!E88 -> 0.953
A7: Average occupancy % - O&M | B7: =Data_Collection!B89 -> 0.976 | C7: =Data_Collection!C89 -> 0.959 | D7: =Data_Collection!D89 -> 0.958 | E7: =Data_Collection!E89 -> 0.953
A8: Period-end occupancy % (O&M) | B8: =Data_Collection!B90 -> 0.976 | C8: =Data_Collection!C90 -> 0.959 | D8: =Data_Collection!D90 -> 0.958 | E8: =Data_Collection!E90 -> 0.953
A9: Leased % (if disclosed) | B9: =Data_Collection!B91 -> 0.978 | C9: =Data_Collection!C91 -> 0.96 | D9: =Data_Collection!D91 -> 0.962 | E9: =Data_Collection!E91 -> 0.958
A11: SAME-STORE NOI
A12: SS NOI growth - cash % | B12: =Data_Collection!B82 -> 0.085 | C12: =Data_Collection!C82 -> 0.045 | D12: =Data_Collection!D82 -> 0.063 | E12: =Data_Collection!E82 -> 0.066
A13: SS NOI growth - net effective % | B13: =Data_Collection!B83 -> 0.075 | C13: =Data_Collection!C83 -> 0.04 | D13: =Data_Collection!D83 -> 0.048 | E13: =Data_Collection!E83 -> 0.051
A14: SS pool size (M sq ft) | B14: =Data_Collection!B84 -> 738498 | C14: =Data_Collection!C84 -> 764587 | D14: =Data_Collection!D84 -> 773176 | E14: =Data_Collection!E84 -> 777055
A16: RENT CHANGE ON ROLLOVER
A17: Net effective rent change % | B17: =Data_Collection!B94 -> 0.741 | C17: =Data_Collection!C94 -> 0.663 | D17: =Data_Collection!D94 -> 0.438 | E17: =Data_Collection!E94 -> 0.319
A18: Cash rent change % | B18: =Data_Collection!B95 -> 0.518 | C18: =Data_Collection!C95 -> 0.401 | D18: =Data_Collection!D95 -> 0.273 | E18: =Data_Collection!E95 -> 0.168
A19: Retention % | B19: =Data_Collection!B96 -> 0.768 | C19: =Data_Collection!C96 -> 0.784 | D19: =Data_Collection!D96 -> 0.777 | E19: =Data_Collection!E96 -> 0.758
A20: Leases commenced/signed (M sq ft) | B20: =Data_Collection!B97 -> 43.65 | C20: =Data_Collection!C97 -> 46.491 | D20: =Data_Collection!D97 -> 43.764 | E20: =Data_Collection!E97 -> 66.722
A22: LEASE EXPIRATION SCHEDULE (forward, annual)
A23: % of NOI expiring Y1 | B23: =Data_Collection!B99 -> 0.091 | C23: =Data_Collection!C99 -> 0.091 | D23: =Data_Collection!D99 -> 0.103 | E23: =Data_Collection!E99 -> 0.069
A24: % expiring Y2 | B24: =Data_Collection!B100 -> 0.12 | C24: =Data_Collection!C100 -> 0.135 | D24: =Data_Collection!D100 -> 0.148 | E24: =Data_Collection!E100 -> 0.147
A25: % expiring Y3 | B25: =Data_Collection!B101 -> 0.139 | C25: =Data_Collection!C101 -> 0.151 | D25: =Data_Collection!D101 -> 0.146 | E25: =Data_Collection!E101 -> 0.147
A26: % expiring Y4 | B26: =Data_Collection!B102 -> 0.148 | C26: =Data_Collection!C102 -> 0.143 | D26: =Data_Collection!D102 -> 0.136 | E26: =Data_Collection!E102 -> 0.14
A27: % expiring Y5 | B27: =Data_Collection!B103 -> 0.146 | C27: =Data_Collection!C103 -> 0.134 | D27: =Data_Collection!D103 -> 0.133 | E27: =Data_Collection!E103 -> 0.133
A29: MARK-TO-MARKET
A30: Lease MTM % (net effective) | B30: =Data_Collection!B106 -> 0.764 | C30: =Data_Collection!C106 -> 0.687 | D30: =Data_Collection!D106 -> 0.501 | E30: =Data_Collection!E106 -> 0.435
A31: MTM embedded NOI $ | B31: =Data_Collection!B107 -> N/D | C31: =Data_Collection!C107 -> N/D | D31: =Data_Collection!D107 -> N/D | E31: =Data_Collection!E107 -> N/D
A33: NOTE: PLD same-store definition (paste verbatim) →

Sheet Development
A1: DEVELOPMENT PIPELINE
A2: Green = link, blue = input, black = calc.
A4: ($ in millions unless noted) | B4: FY2023 | C4: FY2024 | D4: FY2025 | E4: Q1 2026
A5: TOTAL DEVELOPMENT
A6: Starts - TEI ($) | B6: =Data_Collection!B110 -> 3397 | C6: =Data_Collection!C110 -> 1339 | D6: =Data_Collection!D110 -> 2956 | E6: =Data_Collection!E110 -> 1783
A7: Starts - est. yield % | B7: =Data_Collection!B111 -> 0.07 | C7: =Data_Collection!C111 -> 0.073 | D7: =Data_Collection!D111 -> 0.063 | E7: =Data_Collection!E111 -> 0.088
A8: Starts - est. margin % | B8: =Data_Collection!B112 -> 0.274 | C8: =Data_Collection!C112 -> 0.269 | D8: =Data_Collection!D112 -> 0.193 | E8: =Data_Collection!E112 -> 0.32
A9: Starts - est. value creation ($) | B9: =Data_Collection!B113 -> 931 | C9: =Data_Collection!C113 -> 366 | D9: =Data_Collection!D113 -> 569 | E9: =Data_Collection!E113 -> 571
A10: Starts - % build-to-suit | B10: =Data_Collection!B114 -> 0.53 | C10: =Data_Collection!C114 -> 0.334 | D10: =Data_Collection!D114 -> 0.611 | E10: =Data_Collection!E114 -> 0.812
A12: STREAM SPLIT
A13: Data center starts - TEI ($) | B13: =Data_Collection!B115 -> N/D | C13: =Data_Collection!C115 -> N/D | D13: =Data_Collection!D115 -> N/D | E13: =Data_Collection!E115 -> 1300
A14: Logistics starts - TEI ($) | B14: =B6-B10 -> 3396.47 | C14: =C6-C10 -> 1338.666 | D14: =D6-D10 -> 2955.389 | E14: =E6-E10 -> 1782.188
A15: DC % of total starts | B15: =IF(B6=0,0,B10/B6) -> 0.00015602002 | C15: =IF(C6=0,0,C10/C6) -> 0.00024943988 | D15: =IF(D6=0,0,D10/D6) -> 0.00020669824 | E15: =IF(E6=0,0,E10/E6) -> 0.00045541223
A17: STABILIZATIONS
A18: Stabilizations - TEI ($) | B18: =Data_Collection!B116 -> 3151 | C18: =Data_Collection!C116 -> 4168 | D18: =Data_Collection!D116 -> 2260 | E18: =Data_Collection!E116 -> 1113
A19: Stabilizations - est. yield % | B19: =Data_Collection!B117 -> 0.063 | C19: =Data_Collection!C117 -> 0.061 | D19: =Data_Collection!D117 -> 0.067 | E19: =Data_Collection!E117 -> 0.076
A20: Stabilizations - est. margin % | B20: =Data_Collection!B118 -> 0.291 | C20: =Data_Collection!C118 -> 0.185 | D20: =Data_Collection!D118 -> 0.251 | E20: =Data_Collection!E118 -> 0.348
A21: Stabilizations - est. value creation ($) | B21: =Data_Collection!B119 -> 917 | C21: =Data_Collection!C119 -> 773 | D21: =Data_Collection!D119 -> 568 | E21: =Data_Collection!E119 -> 387
A23: PIPELINE & LAND
A24: CIP balance ($) | B24: =Data_Collection!B120 -> 7850 | C24: =Data_Collection!C120 -> 4712 | D24: =Data_Collection!D120 -> 5126 | E24: =Data_Collection!E120 -> 5491
A25: CIP - % leased | B25: =Data_Collection!B121 -> 0.372 | C25: =Data_Collection!C121 -> 0.332 | D25: =Data_Collection!D121 -> 0.548 | E25: =Data_Collection!E121 -> 0.475
A26: Land bank - book value ($) | B26: =Data_Collection!B122 -> 3814 | C26: =Data_Collection!C122 -> 4485 | D26: =Data_Collection!D122 -> 4979 | E26: =Data_Collection!E122 -> 4799
A27: Land bank - buildout TEI capacity ($) | B27: =Data_Collection!B123 -> 37000 | C27: =Data_Collection!C123 -> 38300 | D27: =Data_Collection!D123 -> 39000 | E27: =Data_Collection!E123 -> 38000
A29: DERIVED HISTORY
A30: Realized value-creation margin % (VC ÷ TEI) | B30: =IF(B16=0,0,B19/B16) -> 0 | C30: =IF(C16=0,0,C19/C16) -> 0 | D30: =IF(D16=0,0,D19/D16) -> 0 | E30: =IF(E16=0,0,E19/E16) -> 0

Sheet Strategic_Capital
A1: STRATEGIC CAPITAL
A2: Green = link, blue = input, black = calc.
A4: ($ in millions unless noted) | B4: FY2023 | C4: FY2024 | D4: FY2025 | E4: Q1 2026
A5: AUM ($B)
A6: Gross AUM | B6: =Data_Collection!B126 -> 219 | C6: =Data_Collection!C126 -> 198 | D6: =Data_Collection!D126 -> 230 | E6: =Data_Collection!E126 -> 235
A7: Prologis-share AUM | B7: =Data_Collection!B127 -> 159 | C7: =Data_Collection!C127 -> 136 | D7: =Data_Collection!D127 -> 162 | E7: =Data_Collection!E127 -> 166
A8: Third-party AUM | B8: =B6-B7 -> 60 | C8: =C6-C7 -> 62 | D8: =D6-D7 -> 68 | E8: =E6-E7 -> 69
A10: FEE REVENUE ($)
A11: Recurring asset management fees | B11: =Data_Collection!B128 -> 327456 | C11: =Data_Collection!C128 -> 347540 | D11: =Data_Collection!D128 -> 374044 | E11: =Data_Collection!E128 -> 379020
A12: Transactional fees | B12: =Data_Collection!B129 -> 31801 | C12: =Data_Collection!C129 -> 29126 | D12: =Data_Collection!D129 -> 32512 | E12: =Data_Collection!E129 -> 37142
A13: Total strategic capital revenue | B13: =B11+B12 -> 359257 | C13: =C11+C12 -> 376666 | D13: =D11+D12 -> 406556 | E13: =E11+E12 -> 416162
A14: Strategic capital expenses | B14: =Data_Collection!B131 -> 385542 | C14: =Data_Collection!C131 -> 291856 | D14: =Data_Collection!D131 -> 270517 | E14: =Data_Collection!E131 -> 81889
A16: PROMOTES ($)
A17: Net promote income (expense) | B17: =Data_Collection!B130 -> 478944 | C17: =Data_Collection!C130 -> 31714 | D17: =Data_Collection!D130 -> -48960 | E17: =Data_Collection!E130 -> -50448
A19: CO-INVESTMENT
A20: Contributions to ventures ($) | B20: =Data_Collection!B132 -> 1253395 | C20: =Data_Collection!C132 -> 2306446 | D20: =Data_Collection!D132 -> 1042681 | E20: =Data_Collection!E132 -> 339404
A21: PLD share of venture debt ($) | B21: =Data_Collection!B133 -> 3613882 | C21: =Data_Collection!C133 -> 4653326 | D21: =Data_Collection!D133 -> 5329877 | E21: =Data_Collection!E133 -> 5429782
A22: Effective fee rate (fees ÷ avg 3rd-party AUM) | B22: =IF(B8=0,0,(B11)/(B8*1000)) -> 5.4576 | C22: =IF(C8=0,0,(C11)/(C8*1000)) -> 5.6054839 | D22: =IF(D8=0,0,(D11)/(D8*1000)) -> 5.5006471 | E22: =IF(E8=0,0,(E11)/(E8*1000)) -> 5.4930435

Sheet Capital_Deployment
A1: CAPITAL DEPLOYMENT
A2: Green = link, blue = input, black = calc.
A4: ($ in millions unless noted) | B4: FY2023 | C4: FY2024 | D4: FY2025 | E4: Q1 2026
A5: ACQUISITIONS
A6: Acquisitions ($) | B6: =Data_Collection!B136 -> 732636 | C6: =Data_Collection!C136 -> 1916744 | D6: =Data_Collection!D136 -> 1710000 | E6: =Data_Collection!E136 -> 267930
A7: Acquisitions - wtd avg stabilized cap rate % | B7: =Data_Collection!B137 -> 0.054 | C7: =Data_Collection!C137 -> 0.051 | D7: =Data_Collection!D137 -> 0.047 | E7: =Data_Collection!E137 -> 0.047
A9: DISPOSITIONS & CONTRIBUTIONS [NAV ANCHOR]
A10: Dispositions + contributions ($) | B10: =Data_Collection!B138 -> 1607994 | C10: =Data_Collection!C138 -> 3984920 | D10: =Data_Collection!D138 -> 2170174 | E10: =Data_Collection!E138 -> 676426
A11: Disposition cap rate % [NAV ANCHOR] | B11: =Data_Collection!B139 -> 0.045 | C11: =Data_Collection!C139 -> 0.048 | D11: =Data_Collection!D139 -> 0.049 | E11: =Data_Collection!E139 -> 0.051

Sheet Debt
A1: DEBT SCHEDULE
A2: Green = link, blue = input, black = calc.
A4: ($ in millions unless noted) | B4: FY2023 | C4: FY2024 | D4: FY2025 | E4: Q1 2026
A5: INSTRUMENT DETAIL (one row per note series — fill from 10-K debt footnote)
A6: [Instrument 1 - principal]
A7: [Instrument 2 - principal]
A8: [Instrument 3 - principal]
A10: PORTFOLIO STATS (quarterly)
A11: Wtd avg interest rate % (PLD share) | B11: =Data_Collection!B144 -> 0.03 | C11: =Data_Collection!C144 -> 0.032 | D11: =Data_Collection!D144 -> 0.033 | E11: =Data_Collection!E144 -> 0.033
A12: Wtd avg remaining term (yrs) | B12: =Data_Collection!B145 -> 9.1 | C12: =Data_Collection!C145 -> 9 | D12: =Data_Collection!D145 -> 8.2 | E12: =Data_Collection!E145 -> 8.1
A13: % fixed-rate | B13: =Data_Collection!B146 -> 0.91 | C13: =Data_Collection!C146 -> 0.952 | D13: =Data_Collection!D146 -> 0.962 | E13: =Data_Collection!E146 -> 0.954
A14: % secured (of gross RE assets) | B14: =Data_Collection!B147 -> 0.006 | C14: =Data_Collection!C147 -> 0.005 | D14: =Data_Collection!D147 -> 0.003 | E14: =Data_Collection!E147 -> 0.004
A15: Debt / Adjusted EBITDA (x) | B15: =Data_Collection!B148 -> 4.6 | C15: =Data_Collection!C148 -> 4.6 | D15: =Data_Collection!D148 -> 5.3 | E15: =Data_Collection!E148 -> 4.8
A16: Fixed charge coverage (x) | B16: =Data_Collection!B149 -> 7.9 | C16: =Data_Collection!C149 -> 6.8 | D16: =Data_Collection!D149 -> 5.9 | E16: =Data_Collection!E149 -> 6.4
A17: Available liquidity ($) | B17: =Data_Collection!B152 -> 6000 | C17: =Data_Collection!C152 -> 7400 | D17: =Data_Collection!D152 -> 7600 | E17: =Data_Collection!E152 -> 6700
A19: NEW ISSUANCE SERIES (cost-of-debt input for WACC)
A20: New issuance during period ($) | B20: =Data_Collection!B150 -> 5755 | C20: =Data_Collection!C150 -> 4506 | D20: =Data_Collection!D150 -> 3461 | E20: =Data_Collection!E150 -> 162
A21: New issuance - wtd avg rate % | B21: =Data_Collection!B151 -> 0.047 | C21: =Data_Collection!C151 -> 0.048 | D21: =Data_Collection!D151 -> 0.042 | E21: =Data_Collection!E151 -> 0.037
A23: HEDGE BLOCK
A24: FX hedge notional - EUR ($)
A25: FX hedge notional - GBP ($)
A26: FX hedge notional - JPY ($)
A27: % forecasted earnings USD-or-hedged (note)

Sheet Share_Count
A1: SHARE COUNT
A2: The cardinal rule: Core FFO per-share math uses the units-inclusive Core FFO basis, NOT the EPS basis.
A4: ($ in millions unless noted) | B4: FY2023 | C4: FY2024 | D4: FY2025 | E4: Q1 2026
A5: SHARE COUNTS (M)
A6: Common shares outstanding (period-end) | B6: =Data_Collection!B155 -> 924.4 | C6: =Data_Collection!C155 -> 926.3 | D6: =Data_Collection!D155 -> 929.2 | E6: =Data_Collection!E155 -> 932.3
A7: Wtd avg diluted - EPS basis | B7: =Data_Collection!B156 -> 951.8 | C7: =Data_Collection!C156 -> 953.6 | D7: =Data_Collection!D156 -> 956.8 | E7: =Data_Collection!E156 -> 957.6
A8: Wtd avg shares/units - Core FFO basis | B8: =Data_Collection!B157 -> 952.2 | C8: =Data_Collection!C157 -> 954.1 | D8: =Data_Collection!D157 -> 957.2 | E8: =Data_Collection!E157 -> 960.3
A9: OP/LP units outstanding | B9: =Data_Collection!B158 -> 23.3 | C9: =Data_Collection!C158 -> 23.4 | D9: =Data_Collection!D158 -> 22.1 | E9: =Data_Collection!E158 -> 20
A10: Core FFO basis − EPS basis (units bridge) | B10: =B8-B7 -> 0.4 | C10: =C8-C7 -> 0.5 | D10: =D8-D7 -> 0.4 | E10: =E8-E7 -> 2.7
A11: CHECK: Core FFO basis ≥ EPS basis | B11: =IF(B8="","n/a",IF(B8>=B7,"OK","ERROR")) -> OK | C11: =IF(C8="","n/a",IF(C8>=C7,"OK","ERROR")) -> OK | D11: =IF(D8="","n/a",IF(D8>=D7,"OK","ERROR")) -> OK | E11: =IF(E8="","n/a",IF(E8>=E7,"OK","ERROR")) -> OK
A13: ISSUANCE ACTIVITY
A14: ATM issuance ($) | B14: =Data_Collection!B159 -> 0 | C14: =Data_Collection!C159 -> 0 | D14: =Data_Collection!D159 -> 0 | E14: =Data_Collection!E159 -> 0
A15: ATM issuance (shares) | B15: =Data_Collection!B160 -> 0 | C15: =Data_Collection!C160 -> 0 | D15: =Data_Collection!D160 -> 0 | E15: =Data_Collection!E160 -> 0

Sheet Audit
A1: AUDIT - MODEL HEALTH
A2: Each check returns OK/ERROR. ERROR = model is wrong. Master flag on Cover reads column E.
A4: # | B4: Check | C4: Category | D4: References | E4: Status
A5: 1 | B5: Balance sheet balances (all periods) | C5: Balance sheet | D5: Historicals check row 52 | E5: =IF(SUMPRODUCT(ABS(Historicals!B52:E52))<4,"OK","ERROR") -> OK
A6: 2 | B6: Nareit FFO ties to reported | C6: FFO | D6: FFO_Recon row 12 | E6: =IF(COUNTIF(FFO_Recon!B11:E11,"ERROR")=0,"OK","ERROR") -> OK
A7: 3 | B7: Core FFO/share ties to reported | C7: FFO | D7: FFO_Recon row 32 | E7: =IF(COUNTIF(FFO_Recon!B31:E31,"ERROR")=0,"OK","ERROR") -> OK
A8: 4 | B8: AFFO ties to reported | C8: AFFO | D8: FFO_Recon row 47 | E8: =IF(COUNTIF(FFO_Recon!B46:E46,"ERROR")=0,"OK","ERROR") -> OK
A9: 5 | B9: Core FFO share count ≥ EPS share count | C9: Share count | D9: Share_Count row 11 | E9: =IF(COUNTIF(Share_Count!B11:E11,"ERROR")=0,"OK","ERROR") -> OK
A10: 6 | B10: Debt schedule ties to balance sheet | C10: Debt | D10: Debt tab - wire instrument sum to Historicals debt line | E10: =IF(Debt!B6="","PENDING","REVIEW") -> PENDING
A11: 7 | B11: No hardcodes outside Data_Collection | C11: Hygiene | D11: Manual color audit each session | E11: =IF(1=1,"MANUAL","") -> MANUAL
A12: 8 | B12: Every filled Data_Collection row has a source | C12: Hygiene | D12: Manual review | E12: =IF(1=1,"MANUAL","") -> MANUAL

Sheet Assumptions
A1: PROLOGIS (PLD) - FORECAST ASSUMPTIONS
A2: Scenario-driven inputs for the 5-year forecast. Blue = input (you set). Green = historical reference link. ACTIVE column resolves the chosen case via the scenario switch and is the ONLY column the Model tab reads.
A4: SCENARIO SWITCH | U4: 1
A5: Active scenario (1 = Base, 2 = Bull, 3 = Bear) | B5: 1 | G5: Change this one cell to flip the whole model. Forecast Model reads only the ACTIVE column (E-equivalent resolver per row). | U5: 2
A6: Active scenario name | B6: =CHOOSE($B$5,"BASE","BULL","BEAR") -> BASE | U6: 3
A8: Assumption | B8: Hist. ref. | C8: Base | D8: Bull | E8: Bear | F8: ACTIVE | G8: Source / rationale
A9: 1 · OPERATING ASSUMPTIONS (same-store NOI engine)
A10: Average occupancy % - PLD share | B10: =Drivers!D6 -> 0.956 | C10: 0.953 | D10: 0.957 | E10: 0.935 | F10: =CHOOSE($B$5,C10,D10,E10) -> 0.953 | G10: Hist = FY2025. Base: hold guided 95.0–95.75% band then flat. Bull: upper band. Bear: 150–250bps erosion (recession proxy). Lever 2.
A11: Market rent growth - Y1 (annual) | B11: N/A | C11: 0.03 | D11: 0.06 | E11: -0.01 | F11: =CHOOSE($B$5,C11,D11,E11) -> 0.03 | G11: Lever 1. Base: modest mean-reverting. Bull: supply-trough re-accel. Bear: renewed declines. Largest compounding effect on SS NOI.
A12: Market rent growth - terminal (Y5) | B12: N/A | C12: 0.035 | D12: 0.055 | E12: 0.01 | F12: =CHOOSE($B$5,C12,D12,E12) -> 0.035 | G12: Path glides Y1→Y5; set endpoints here, interpolate in Model. Keep bull below boom-era peaks.
A13: Contractual escalators (in-place) | B13: N/A | C13: 0.04 | D13: 0.045 | E13: 0.035 | F13: =CHOOSE($B$5,C13,D13,E13) -> 0.04 | G13: Embedded annual bumps on in-place leases — the floor under SS NOI. Tight band; not a recession lever.
A14: SS NOI growth - sanity ceiling (cash) | B14: =Drivers!D12 -> 0.063 | G14: Hist = FY2025 cash SS NOI +6.3%. Reference only; SS NOI growth is an OUTPUT of the Model bridge, not an input here.
A15: Operating expense ratio (rental) | B15: N/A | C15: 0.245 | D15: 0.24 | E15: 0.255 | F15: =CHOOSE($B$5,C15,D15,E15) -> 0.245 | G15: Rental exp ÷ rental rev. Used to gross NOI up to revenue. Hist ~24% (Historicals). Slight scenario flex on margin.
A17: 2 · LEASING ASSUMPTIONS (rollover / mark-to-market runway)
A18: Net effective rent change on rollover - Y1 | B18: =Drivers!D17 -> 0.438 | C18: 0.3 | D18: 0.4 | E18: 0.18 | F18: =CHOOSE($B$5,C18,D18,E18) -> 0.3 | G18: Hist = FY2025 +43.8%. Base decays from here (MTM is a depleting stock). Lever 3.
A19: Rollover spread - terminal (Y5) | B19: N/A | C19: 0.1 | D19: 0.22 | E19: 0.03 | F19: =CHOOSE($B$5,C19,D19,E19) -> 0.1 | G19: Decay endpoint. If market rents flat, spread converges to escalator levels. Constant 30%+ forever = classic bull error.
A20: Annual MTM realization (% pool rolling) | B20: =Drivers!D23 -> 0.103 | C20: 0.13 | D20: 0.15 | E20: 0.11 | F20: =CHOOSE($B$5,C20,D20,E20) -> 0.13 | G20: Hist = FY2025 % NOI expiring Y1 (~10.3%). % of pool that reprices each year, from lease-expiry schedule.
A21: Retention % | B21: =Drivers!D19 -> 0.777 | C21: 0.77 | D21: 0.8 | E21: 0.72 | F21: =CHOOSE($B$5,C21,D21,E21) -> 0.77 | G21: Hist = FY2025 77.7%. Higher retention lowers downtime/turnover cost; bear leaks.
A22: Embedded MTM stock (net effective) | B22: =Drivers!D30 -> 0.501 | C22: 0.5 | D22: 0.5 | E22: 0.5 | F22: =CHOOSE($B$5,C22,D22,E22) -> 0.5 | G22: Hist = FY2025 lease MTM 50.1%. Starting embedded upside that depletes as leases roll; decay path set above.
A24: 3 · DEVELOPMENT ASSUMPTIONS (Approach B - logistics + data centers as separate streams)
A25: Logistics starts - TEI Y1 ($mm) | B25: =Drivers!D14/1000 -> 773.176 | C25: 4000 | D25: 5500 | E25: 2500 | F25: =CHOOSE($B$5,C25,D25,E25) -> 4000 | G25: Hist = FY2025 logistics starts. Base: guidance yr1 ($3.5–4.5B PLD share) then policy. Lever 4. (units $mm)
A26: Logistics starts - annual growth | B26: N/A | C26: 0.05 | D26: 0.12 | E26: -0.2 | F26: =CHOOSE($B$5,C26,D26,E26) -> 0.05 | G26: Years 2–5 growth off Y1. Bear sharply curtails. Drives delivered NOI + AUM feed.
A27: Logistics - stabilized yield on cost | B27: =Development!D19 -> 0.067 | C27: 0.065 | D27: 0.075 | E27: 0.055 | F27: =CHOOSE($B$5,C27,D27,E27) -> 0.065 | G27: Hist ref = FY2025 stabilization yield 6.7%. Lever 5 (value-creation engine).
A28: Logistics - value-creation margin | B28: =Development!D20 -> 0.251 | C28: 0.2 | D28: 0.3 | E28: 0.05 | F28: =CHOOSE($B$5,C28,D28,E28) -> 0.2 | G28: Hist = FY2025 stabilization margin 25.1%. "Is development worth anything" in one cell. Bear compresses toward zero.
A29: Data center starts - TEI Y1 ($mm) | B29: =Development!E13 -> 1300 | C29: 1300 | D29: 2500 | E29: 500 | F29: =CHOOSE($B$5,C29,D29,E29) -> 1300 | G29: Hist = Q1 2026 DC starts $1.3B (first disclosed). Separate stream: longer build, ~100% BTS, higher TEI/project.
A30: Data center - annual growth | B30: N/A | C30: 0.1 | D30: 0.25 | E30: -0.3 | F30: =CHOOSE($B$5,C30,D30,E30) -> 0.1 | G30: DC pivot accel in bull; capital-hungry & competitive in bear. Inference-based (limited disclosure).
A31: Data center - stabilized yield on cost | B31: N/A | C31: 0.08 | D31: 0.09 | E31: 0.065 | F31: =CHOOSE($B$5,C31,D31,E31) -> 0.08 | G31: Q1 2026 starts yield 8.8% (blended). DC carries different economics; footnote mix-shift risk.
A32: Data center - value-creation margin | B32: N/A | C32: 0.25 | D32: 0.35 | E32: 0.1 | F32: =CHOOSE($B$5,C32,D32,E32) -> 0.25 | G32: Higher than logistics on BTS de-risking; bear imports compressed post-2022 logistics margins as caution.
A33: Stabilization lag (quarters, both streams) | B33: N/A | C33: 6 | D33: 5 | E33: 7 | F33: =CHOOSE($B$5,C33,D33,E33) -> 6 | G33: Quarters from start to NOI in operating pool. DC longer than logistics in practice — simplify to one lag, footnote.
A34: Development → contribution share (AUM feed) | B34: N/A | C34: 0.4 | D34: 0.5 | E34: 0.2 | F34: =CHOOSE($B$5,C34,D34,E34) -> 0.4 | G34: % of stabilized TEI contributed to ventures (the conveyor exit ramp into Strategic Capital AUM).
A36: 4 · STRATEGIC CAPITAL ASSUMPTIONS (fee + promote engine)
A37: Effective fee rate (bps of 3rd-party AUM) | B37: =Strategic_Capital!D22 -> 5.5006471 | C37: 0.0055 | D37: 0.0058 | E37: 0.005 | F37: =CHOOSE($B$5,C37,D37,E37) -> 0.0055 | G37: Hist = FY2025 ~55bps (fees ÷ avg 3rd-party AUM). Trailing 3yr, held ~flat. Mix-shift risk footnoted, not modeled.
A38: Third-party AUM growth (annual) | B38: N/A | C38: 0.05 | D38: 0.1 | E38: -0.05 | F38: =CHOOSE($B$5,C38,D38,E38) -> 0.05 | G38: Contribution-driven base. Bull: new vehicle wins ($2.8B Q1 JVs). Bear: net outflows + negative marks. Lever 6.
A39: Transactional fee growth | B39: N/A | C39: 0.03 | D39: 0.08 | E39: -0.1 | F39: =CHOOSE($B$5,C39,D39,E39) -> 0.03 | G39: Tied to deployment pace; lumpier than recurring fees.
A40: Net promote income - FY2026 ($mm) | B40: =Strategic_Capital!D17/1000 -> -48.96 | C40: -50 | D40: -50 | E40: -50 | F40: =CHOOSE($B$5,C40,D40,E40) -> -50 | G40: Hist = FY2025 net promote $(49)M. Base = guided FY26 $(50)M. All cases anchor yr1 to guidance. Lever 8.
A41: Net promote - FY2027+ ($mm/yr) | B41: N/A | C41: 0 | D41: 150 | E41: -50 | F41: =CHOOSE($B$5,C41,D41,E41) -> 0 | G41: Base = ZERO (honest expectation; unforecastable timing — say so loudly). Bull: modest positive. Bear: recurring expense. Asymmetry display.
A42: Strategic capital expense ratio | B42: N/A | C42: 0.55 | D42: 0.52 | E42: 0.58 | F42: =CHOOSE($B$5,C42,D42,E42) -> 0.55 | G42: SC expenses ÷ recurring+transactional fees. Drives FRE margin. Hist noisy (promote-comp timing).
A44: 5 · CAPITAL STRUCTURE ASSUMPTIONS (debt ladder + leverage policy)
A45: New-issue debt cost (all-in %) | B45: =Debt!D21 -> 0.042 | C45: 0.05 | D45: 0.0425 | E45: 0.06 | F45: =CHOOSE($B$5,C45,D45,E45) -> 0.05 | G45: Hist = FY2025 new-issue 4.2%. Base: current curve + spread. Bull: −75bps. Bear: +100bps. Lever 7 (refi drag).
A46: Leverage policy - Net debt / Adj. EBITDA | B46: =Debt!D15 -> 5.3 | C46: 4.8 | D46: 4.5 | E46: 5.5 | F46: =CHOOSE($B$5,C46,D46,E46) -> 4.8 | G46: Hist = FY2025 5.3x (Q1 4.8x). Target band 4.5–5.0x. Incremental debt sized to hold this roughly constant.
...

Sheet Model
A1: PROLOGIS (PLD) - 5 YEAR INTEGRATED FORECAST
A2: Driven entirely by Assumptions!ACTIVE column (col F) - flip Assumptions!B5 to reprice every line. FY2025 (col B) = actual anchor (green links). Forecast FY2026–FY2030 (cols C–G).
A4: ($ in thousands) | B4: FY2025A | C4: FY2026E | D4: FY2027E | E4: FY2028E | F4: FY2029E | G4: FY2030E | H4: ="Scenario: "&Assumptions!B6 -> Scenario: BASE
A5: 1 · OPERATING FORECAST
A6: Average occupancy % - PLD share | B6: =Drivers!D6 -> 0.956 | C6: =Assumptions!$F$10 -> 0.953 | D6: =Assumptions!$F$10 -> 0.953 | E6: =Assumptions!$F$10 -> 0.953 | F6: =Assumptions!$F$10 -> 0.953 | G6: =Assumptions!$F$10 -> 0.953 | H6: Held at ACTIVE occupancy (level). Assumptions r10. Lever 2.
A7: Occupancy delta vs prior (bps→%) | B7: ="" | C7: =C6-B6 -> -0.003 | D7: =D6-C6 -> 0 | E7: =E6-D6 -> 0 | F7: =F6-E6 -> 0 | G7: =G6-F6 -> 0 | H7: Year-over-year occupancy change → SS NOI contribution.
A8: Market rent growth (glide Y1→terminal) | B8: ="" | C8: =Assumptions!$F$11 -> 0.03 | D8: =Assumptions!$F$11+(Assumptions!$F$12-Assumptions!$F$11)*1/4 -> 0.03125 | E8: =Assumptions!$F$11+(Assumptions!$F$12-Assumptions!$F$11)*2/4 -> 0.0325 | F8: =Assumptions!$F$11+(Assumptions!$F$12-Assumptions!$F$11)*3/4 -> 0.03375 | G8: =Assumptions!$F$12 -> 0.035 | H8: Linear glide: Y1 (Assump r11) → Y5 terminal (r12). Lever 1.
A9: Contractual escalators (in-place) | B9: ="" | C9: =Assumptions!$F$13 -> 0.04 | D9: =Assumptions!$F$13 -> 0.04 | E9: =Assumptions!$F$13 -> 0.04 | F9: =Assumptions!$F$13 -> 0.04 | G9: =Assumptions!$F$13 -> 0.04 | H9: Embedded annual bumps. Assumptions r13. Floor under SS NOI.
A10: Rollover spread (decaying Y1→terminal) | B10: =Drivers!D17 -> 0.438 | C10: =Assumptions!$F$18 -> 0.3 | D10: =Assumptions!$F$18+(Assumptions!$F$19-Assumptions!$F$18)*1/4 -> 0.25 | E10: =Assumptions!$F$18+(Assumptions!$F$19-Assumptions!$F$18)*2/4 -> 0.2 | F10: =Assumptions!$F$18+(Assumptions!$F$19-Assumptions!$F$18)*3/4 -> 0.15 | G10: =Assumptions!$F$19 -> 0.1 | H10: MTM stock depletes: spread glides Y1 (r18) → terminal (r19). Lever 3.
A11: MTM realization (% pool rolling) | B11: =Drivers!D23 -> 0.103 | C11: =Assumptions!$F$20 -> 0.13 | D11: =Assumptions!$F$20 -> 0.13 | E11: =Assumptions!$F$20 -> 0.13 | F11: =Assumptions!$F$20 -> 0.13 | G11: =Assumptions!$F$20 -> 0.13 | H11: % of pool repricing each year. Assumptions r20.
A12: Rollover NOI contribution | B12: ="" | C12: =C10*C11 -> 0.039 | D12: =D10*D11 -> 0.0325 | E12: =E10*E11 -> 0.026 | F12: =F10*F11 -> 0.0195 | G12: =G10*G11 -> 0.013 | H12: rollover spread × % pool rolling. The contracted-growth runway.
A13: Same-store NOI growth % | B13: =Drivers!D12 -> 0.063 | C13: =C9+C7+C12 -> 0.076 | D13: =D9+D7+D12 -> 0.0725 | E13: =E9+E7+E12 -> 0.066 | F13: =F9+F7+F12 -> 0.0595 | G13: =G9+G7+G12 -> 0.053 | H13: escalators + occupancy delta + rollover contribution. output of the bridge.
A15: Property NOI | B15: =Historicals!D31 -> 6194767 | C15: =B15*(1+C13) -> 6665569.3 | D15: =C15*(1+D13) -> 7148823.1 | E15: =D15*(1+E13) -> 7620645.4 | F15: =E15*(1+F13) -> 8074073.8 | G15: =F15*(1+G13) -> 8501999.7 | H15: Same-store base compounds at SS NOI growth. Development NOI added below (rDEV).
A16: Operating expense ratio | B16: =-Historicals!D10/Historicals!D6 -> 0.2407354 | C16: =Assumptions!$F$15 -> 0.245 | D16: =Assumptions!$F$15 -> 0.245 | E16: =Assumptions!$F$15 -> 0.245 | F16: =Assumptions!$F$15 -> 0.245 | G16: =Assumptions!$F$15 -> 0.245 | H16: Assumptions r15. Rental exp ÷ rental rev.
A17: Rental revenue | B17: =Historicals!D6 -> 8158904 | C17: =C36/(1-C16) -> 8966571.4 | D17: =D36/(1-D16) -> 10088762 | E17: =E36/(1-E16) -> 11226805 | F17: =F36/(1-F16) -> 12373716 | G17: =G36/(1-G16) -> 13522501 | H17: total property noi (R36) ÷ (1 − opex ratio). Revenue is an OUTPUT.
A18: Rental expenses | B18: =Historicals!D10 -> -1964137 | C18: =-(C17-C36) -> -2196810 | D18: =-(D17-D36) -> -2471746.6 | E18: =-(E17-E36) -> -2750567.1 | F18: =-(F17-F36) -> -3031560.5 | G18: =-(G17-G36) -> -3313012.8 | H18: −(rental revenue − Property NOI).
A20: 2 · DEVELOPMENT FORECAST (Approach B - two streams; $mm except NOI in $000s)
A21: LOGISTICS
A22: Logistics starts - TEI ($mm) | B22: =Development!D14/1000 -> 2.955389 | C22: =Assumptions!$F$25 -> 4000 | D22: =C22*(1+Assumptions!$F$26) -> 4200 | E22: =D22*(1+Assumptions!$F$26) -> 4410 | F22: =E22*(1+Assumptions!$F$26) -> 4630.5 | G22: =F22*(1+Assumptions!$F$26) -> 4862.025 | H22: Y1 = Assump r25 (guidance); grows at r26. Lever 4. $mm.
A23: Logistics - stabilized yield on cost | B23: =Development!D19 -> 0.067 | C23: =Assumptions!$F$27 -> 0.065 | D23: =Assumptions!$F$27 -> 0.065 | E23: =Assumptions!$F$27 -> 0.065 | F23: =Assumptions!$F$27 -> 0.065 | G23: =Assumptions!$F$27 -> 0.065 | H23: Assumptions r27.
A24: Logistics - value-creation margin | B24: =Development!D20 -> 0.251 | C24: =Assumptions!$F$28 -> 0.2 | D24: =Assumptions!$F$28 -> 0.2 | E24: =Assumptions!$F$28 -> 0.2 | F24: =Assumptions!$F$28 -> 0.2 | G24: =Assumptions!$F$28 -> 0.2 | H24: Assumptions r28. Lever 5.
A25: Logistics stabilizations - TEI ($mm) | B25: =Development!D18 -> 2260 | C25: =B22 -> 2.955389 | D25: =C22 -> 4000 | E25: =D22 -> 4200 | F25: =E22 -> 4410 | G25: =F22 -> 4630.5 | H25: prior-year starts (≈6-qtr lag, Assump r33, simplified to 1yr in annual cols - see Notes).)
A26: Logistics delivered NOI ($000s) | B26: ="" | C26: =C25*1000*C23 -> 192.10029 | D26: =D25*1000*D23 -> 260000 | E26: =E25*1000*E23 -> 273000 | F26: =F25*1000*F23 -> 286650 | G26: =G25*1000*G23 -> 300982.5 | H26: stabilized tei × yield, ×1000 to $000s.
A27: DATA CENTERS
A28: DC starts - TEI ($mm) | B28: =Development!E13 -> 1300 | C28: =Assumptions!$F$29 -> 1300 | D28: =C28*(1+Assumptions!$F$30) -> 1430 | E28: =D28*(1+Assumptions!$F$30) -> 1573 | F28: =E28*(1+Assumptions!$F$30) -> 1730.3 | G28: =F28*(1+Assumptions!$F$30) -> 1903.33 | H28: Y1 = Assump r29; grows at r30. Separate stream.
A29: DC - stabilized yield on cost | B29: ="" | C29: =Assumptions!$F$31 -> 0.08 | D29: =Assumptions!$F$31 -> 0.08 | E29: =Assumptions!$F$31 -> 0.08 | F29: =Assumptions!$F$31 -> 0.08 | G29: =Assumptions!$F$31 -> 0.08 | H29: Assumptions r31.
A30: DC - value-creation margin | B30: ="" | C30: =Assumptions!$F$32 -> 0.25 | D30: =Assumptions!$F$32 -> 0.25 | E30: =Assumptions!$F$32 -> 0.25 | F30: =Assumptions!$F$32 -> 0.25 | G30: =Assumptions!$F$32 -> 0.25 | H30: Assumptions r32.
A31: DC stabilizations - TEI ($mm) | B31: ="" | C31: =B28 -> 1300 | D31: =C28 -> 1300 | E31: =D28 -> 1430 | F31: =E28 -> 1573 | G31: =F28 -> 1730.3 | H31: prior-year dc starts (longer build in reality - see Notes).)
A32: DC delivered NOI ($000s) | B32: ="" | C32: =C31*1000*C29 -> 104000 | D32: =D31*1000*D29 -> 104000 | E32: =E31*1000*E29 -> 114400 | F32: =F31*1000*F29 -> 125840 | G32: =G31*1000*G29 -> 138424 | H32: stabilized tei × yield, ×1000.
A33: Total development NOI delivered (cumulative) | B33: ="" | C33: =C26+C32 -> 104192.1 | D33: =C33+D26+D32 -> 468192.1 | E33: =D33+E26+E32 -> 855592.1 | F33: =E33+F26+F32 -> 1268082.1 | G33: =F33+G26+G32 -> 1707488.6 | H33: Cumulative NOI from stabilized developments entering the operating pool.
A34: Stabilized TEI → contributions (AUM feed, $mm) | B34: ="" | C34: =(C25+C31)*Assumptions!$F$34 -> 521.18216 | D34: =(D25+D31)*Assumptions!$F$34 -> 2120 | E34: =(E25+E31)*Assumptions!$F$34 -> 2252 | F34: =(F25+F31)*Assumptions!$F$34 -> 2393.2 | G34: =(G25+G31)*Assumptions!$F$34 -> 2544.32 | H34: stabilized tei × contribution share (Assump r34). Feeds Strategic Capital + Deployment.
A36: TOTAL PROPERTY NOI (same-store + development) | B36: =Historicals!D31 -> 6194767 | C36: =C15+C33 -> 6769761.4 | D36: =D15+D33 -> 7617015.2 | E36: =E15+E33 -> 8476237.5 | F36: =F15+F33 -> 9342155.9 | G36: =G15+G33 -> 10209488 | H36: Same-store NOI (r15) + cumulative development NOI (r33).
A38: 3 · STRATEGIC CAPITAL FORECAST (AUM in $B; fees/promotes in $000s)
A39: Third-party AUM ($B) | B39: =Strategic_Capital!D8 -> 68 | C39: =B39*(1+Assumptions!$F$38) -> 71.4 | D39: =C39*(1+Assumptions!$F$38) -> 74.97 | E39: =D39*(1+Assumptions!$F$38) -> 78.7185 | F39: =E39*(1+Assumptions!$F$38) -> 82.654425 | G39: =F39*(1+Assumptions!$F$38) -> 86.787146 | H39: Grows at Assump r38 (contribution-driven). Lever 6.
A40: Gross AUM ($B) | B40: =Strategic_Capital!D6 -> 230 | C40: =B40*(1+Assumptions!$F$38) -> 241.5 | D40: =C40*(1+Assumptions!$F$38) -> 253.575 | E40: =D40*(1+Assumptions!$F$38) -> 266.25375 | F40: =E40*(1+Assumptions!$F$38) -> 279.56644 | G40: =F40*(1+Assumptions!$F$38) -> 293.54476 | H40: Tracks 3rd-party AUM growth.
A41: Avg 3rd-party AUM ($B) | B41: ="" | C41: =(B39+C39)/2 -> 69.7 | D41: =(C39+D39)/2 -> 73.185 | E41: =(D39+E39)/2 -> 76.84425 | F41: =(E39+F39)/2 -> 80.686463 | G41: =(F39+G39)/2 -> 84.720786 | H41: Average of opening/closing for fee calc.
A42: Recurring fee revenue ($000s) | B42: =Strategic_Capital!D11 -> 374044 | C42: =C41*1000000*Assumptions!$F$37 -> 383350 | D42: =D41*1000000*Assumptions!$F$37 -> 402517.5 | E42: =E41*1000000*Assumptions!$F$37 -> 422643.38 | F42: =F41*1000000*Assumptions!$F$37 -> 443775.54 | G42: =G41*1000000*Assumptions!$F$37 -> 465964.32 | H42: avg 3rd-party aum ($b→$000s) × effective fee rate (Assump r37).)
A43: Transactional fees ($000s) | B43: =Strategic_Capital!D12 -> 32512 | C43: =B43*(1+Assumptions!$F$39) -> 33487.36 | D43: =C43*(1+Assumptions!$F$39) -> 34491.981 | E43: =D43*(1+Assumptions!$F$39) -> 35526.74 | F43: =E43*(1+Assumptions!$F$39) -> 36592.542 | G43: =F43*(1+Assumptions!$F$39) -> 37690.319 | H43: Grows at Assump r39; tied to deployment pace.
A44: Strategic capital expenses ($000s) | B44: =Historicals!D11 -> -270517 | C44: =-(C42+C43)*Assumptions!$F$42 -> -229260.55 | D44: =-(D42+D43)*Assumptions!$F$42 -> -240355.21 | E44: =-(E42+E43)*Assumptions!$F$42 -> -251993.56 | F44: =-(F42+F43)*Assumptions!$F$42 -> -264202.45 | G44: =-(G42+G43)*Assumptions!$F$42 -> -277010.05 | H44: −(recurring+transactional fees) × expense ratio (Assump r42).
A45: Net promote income (expense) ($000s) | B45: =Strategic_Capital!D17 -> -48960 | C45: =Assumptions!$F$40*1000 -> -50000 | D45: =Assumptions!$F$41*1000 -> 0 | E45: =Assumptions!$F$41*1000 -> 0 | F45: =Assumptions!$F$41*1000 -> 0 | G45: =Assumptions!$F$41*1000 -> 0 | H45: KEPT SEPARATE. FY26 = Assump r40 (guided); FY27+ = r41. Base FY27+ = 0. Lever 8. ×1000 to $000s.
...

Sheet DCF
A1: PROLOGIS (PLD) - DISCOUNTED CASH FLOW (DCF)
A2: Equity DCF on AFFO. AFFO is a levered (post-interest) cash flow, so its present value IS equity value - no debt is subtracted (that would double-count leverage); Enterprise Value is shown as a derived reconciliation. Discount rate & terminal growth link to Assumptions and flex with the scenario switch. $ in thousands unless noted.
A3: ($ in thousands) | B3: FY2026E | C3: FY2027E | D3: FY2028E | E3: FY2029E | F3: FY2030E | G3: Total / Term.
A4: 1 · DISCOUNT RATE & TERMINAL ASSUMPTIONS (linked from Assumptions)
A5: Equity discount rate (Assumptions r59) | B5: =Assumptions!F59 -> 0.075 | H5: Linked to Assumptions r59 (ACTIVE, switch-driven; Base 7.50% / Bull 7.00% / Bear 8.50%). Scoped there as "WACC/discount rate"; used here as the EQUITY discount rate for the levered AFFO stream. For a pure cost-of-equity one would typically set this ~100bps above WACC - adjustable in Assumptions.
A6: Terminal growth g (Assumptions r62) | B6: =Assumptions!F62 -> 0.025 | H6: Linked to Assumptions r62 (Base 2.5% / Bull 3.0% / Bear 1.5%). Bounded by long-run rent/inflation; g ≤ inflation+1%.
A7: Spread (discount rate − g) | B7: =B5-B6 -> 0.05
A8: Memo: 10- yr UST risk- free (Data_Collection) | B8: =Data_Collection!E164 -> 0.0449
A9: Memo: exit/terminal cap rate (Assumptions r60) | B9: =Assumptions!F60 -> 0.05
A10: 2 · FORECAST CASH FLOWS (from Model FY2026–FY2030)
A11: AFFO - PRIMARY cash- flow stream | B11: =Model!C76 -> 4381246.6 | C11: =Model!D76 -> 4988947.7 | D11: =Model!E76 -> 5574011.2 | E11: =Model!F76 -> 6160199.4 | F11: =Model!G76 -> 6743041.2 | H11: Green link to Model r76. AFFO = cash earnings to common+OP-unit holders after recurring capex and TI/LC. The equity claim.
A12: AFFO per share ($) | B12: =Model!C77 -> 4.508283 | C12: =Model!D77 -> 5.0572869 | D12: =Model!E77 -> 5.5673504 | E12: =Model!F77 -> 6.0634871 | F12: =Model!G77 -> 6.5418926
A13: Core FFO - cross- check stream | B13: =Model!C72 -> 5620572 | C13: =Model!D72 -> 6400173.7 | D13: =Model!E72 -> 7150734.5 | E13: =Model!F72 -> 7902738 | F13: =Model!G72 -> 8650448.5 | H13: Core FFO includes non-cash items AFFO removes (straight-line rent, etc.); used only as an upper-bound cross-check (Section 6).
A14: Core FFO per share ($) | B14: =Model!C73 -> 5.7835432 | C14: =Model!D73 -> 6.4878441 | D14: =Model!E73 -> 7.1421895 | E14: =Model!F73 -> 7.7786686 | F14: =Model!G73 -> 8.3924009
A15: 3 · DISCOUNT FACTORS & PV OF EXPLICIT AFFO (end- of- year convention)
A16: Period (t, years) | B16: 1 | C16: 2 | D16: 3 | E16: 4 | F16: 5
A17: Discount factor = 1/(1+r)^t | B17: =1/(1+$B$5)^B16 -> 0.93023256 | C17: =1/(1+$B$5)^C16 -> 0.86533261 | D17: =1/(1+$B$5)^D16 -> 0.80496057 | E17: =1/(1+$B$5)^E16 -> 0.74880053 | F17: =1/(1+$B$5)^F16 -> 0.69655863
A18: PV of AFFO ($000s) | B18: =B11*B17 -> 4075578.3 | C18: =C11*C17 -> 4317099.1 | D18: =D11*D17 -> 4486859.2 | E18: =E11*E17 -> 4612760.6 | F18: =F11*F17 -> 4696923.5 | G18: =SUM(B18:F18) -> 22189221 | H18: Each year: AFFO × discount factor. Total (col G) = PV of the explicit 5-year AFFO stream.
A20: 4 · TERMINAL VALUE - GORDON GROWTH
A21: Terminal- year AFFO (FY2030) | B21: =F11 -> 6743041.2
A22: Terminal AFFO × (1+g) | B22: =B21*(1+$B$6) -> 6911617.2
A23: Terminal value = AFFO₍FY30₎×(1+g)/(r−g) | B23: =B22/($B$5-$B$6) -> 1.3823234e+08 | H23: Gordon-growth perpetuity at the end of FY2030 (undiscounted).
A24: Discount factor at t = 5 | B24: =F17 -> 0.69655863
A25: PV of terminal value ($000s) | B25: =B23*B24 -> 96286932
A26: Memo: implied terminal AFFO multiple (TV ÷ AFFO₍FY30₎) | B26: =B23/B21 -> 20.5 | H26: Equals 1/(r−g) applied to forward AFFO. Sanity-check vs where quality REITs trade on AFFO.
A28: 5 · DCF VALUATION
A29: PV of explicit AFFO (FY2026–2030) | B29: =G18 -> 22189221
A30: + PV of terminal value | B30: =B25 -> 96286932
A31: EQUITY VALUE ($000s) | B31: =B29+B30 -> 1.1847615e+08 | H31: PV of the AFFO (equity) stream + PV of terminal value. AFFO accrues to equity, so this is equity value directly - NO debt subtraction.
A32: ÷ Core FFO share/unit count (M) | B32: =Share_Count!D8 -> 957.2
A33: DCF VALUE PER SHARE ($) | B33: =B31/1000/B32 -> 123.77367
A34: Memo: TV as % of equity value | B34: =B30/B31 -> 0.8127115
A35: Implied ENTERPRISE VALUE (reconciliation) | B35: =B31+(Data_Collection!E33-Data_Collection!E143)+Data_Collection!E37+Data_Collection!E39-Data_Collection!E30 -> 1.5731903e+08 | H35: Derived: Equity + net debt (face − cash) + preferred + NCI. EV is reconciled FROM equity because AFFO is an equity stream (the reverse of an unlevered-FCF DCF).
A36: Current share price ($) | B36: =NAV!B79 -> 145 | H36: Linked to the current-price input already on the NAV tab (single source).
A37: Implied upside / (downside) to DCF value | B37: =B33/B36-1 -> -0.14638851
A39: 6 · CORE FFO CROSS- CHECK (secondary; upper bound)
A40: PV of explicit Core FFO ($000s) | B40: =SUMPRODUCT(B13:F13,B17:F17) -> 28465896
A41: Terminal value on Core FFO | B41: =F13*(1+$B$6)/($B$5-$B$6) -> 1.7733419e+08
A42: + PV terminal (Core FFO) | B42: =B41*F17 -> 1.2352366e+08
A43: Equity value - Core FFO basis ($000s) | B43: =B40+B42 -> 1.5198956e+08
...

Sheet NAV
A1: PROLOGIS (PLD) - NET ASSET VALUE (NAV)
A2: Sum-of-the-parts on a Prologis-share economic basis. Bull/Bear columns flex operating NOI (captured from the Model), cap rate and development margins / FRE multiple; CIP, land and FRE are held at snapshot levels across cases. Balance sheet as of Q1 2026.
A3: ⚠ Reference state = BASE (Assumptions!B5 = 1). The Base column's NOI (r7/r8) and FRE (r35) link to the ACTIVE scenario, so keep the switch on Base when reading this tab; Bull/Bear NOI are static captures (r7/r8, blue). Switch-independent three-scenario assembly is the Scenarios tab's role (next phase).
A4: ($ in thousands unless noted) | B4: Base | C4: Bull | D4: Bear | E4: Source / methodology
A5: 1 · STABILIZED NOI (Section 1)
A6: Stabilized forecast year selected | B6: FY2026E | C6: FY2026E | D6: FY2026E | E6: Forward / NTM year. Nearest forward period: rents are already marked toward market via the FY2026 bridge and occupancy sits at the stabilized ~95.3% level in the model, so minimal normalization is required. Standard forward-NOI NAV convention.
